Workbook
Name _____TVL1: #REF!
Name _____TVL1: #REF!
Name _____TVL1: #REF!
Name _____TVL1: #REF!
Name _____TVL1: #REF!
Name ____TVL1: #REF!
Name ____TVL1: #REF!
Name ____TVL1: #REF!
Name ____TVL1: #REF!
Name ____TVL1: #REF!
Name ___TVL1: #REF!
Name ___TVL1: #REF!
Name ___TVL1: #REF!
Name ___TVL1: #REF!
Name ___TVL1: #REF!
Name __TVL1: #REF!
Name __TVL1: #REF!
Name __TVL1: #REF!
Name __TVL1: #REF!
Name __TVL1: #REF!
Name _TVL1: #REF!
Name _TVL1: #REF!
Name _TVL1: #REF!
Name _TVL1: #REF!
Name _TVL1: #REF!
Name A: {"ÿÿÿÿÿ"}
Name accessories: 0.2
Name D: {"ÿÿÿÿÿ"}
Name dau: #REF!,#REF!,#REF!,#REF!,#REF!
Name dau: #REF!,#REF!,#REF!,#REF!,#REF!
Name dau: #REF!,#REF!,#REF!,#REF!,#REF!
Name dau: #REF!,#REF!,#REF!,#REF!,#REF!
Name dau: #REF!,#REF!,#REF!,#REF!,#REF!
Name dgnckeoday: 10%
Name dgnclaptrunking: 6%
Name Document_array: {"ÿÿÿÿÿ"}
Name dongia: #REF!
Name dongia: #REF!
Name dongia: #REF!
Name dongia: #REF!
Name dongia: #REF!
Name hide: #REF!,#REF!,#REF!,#REF!,#REF!
Name hide: #REF!,#REF!,#REF!,#REF!,#REF!
Name hide: #REF!,#REF!,#REF!,#REF!,#REF!
Name hide: #REF!,#REF!,#REF!,#REF!,#REF!
Name hide: #REF!,#REF!,#REF!,#REF!,#REF!
Name hihe1: #REF!,#REF!,#REF!,#REF!,#REF!,#REF!,#REF!
Name hihe1: #REF!,#REF!,#REF!,#REF!,#REF!,#REF!,#REF!
Name hihe1: #REF!,#REF!,#REF!,#REF!,#REF!,#REF!,#REF!
Name hihe1: #REF!,#REF!,#REF!,#REF!,#REF!,#REF!,#REF!
Name hihe1: #REF!,#REF!,#REF!,#REF!,#REF!,#REF!,#REF!
Name HS: #REF!
Name HS: #REF!
Name HS: #REF!
Name HS: #REF!
Name HS: #REF!
Name HSlabor: 0.15
Name hsnc: 0.08
Name hsnc_bms: 10%
Name hstb: 1

Sheet 예산관리
E4: Ⅳ. 예산관리
F6: ■ | G6: 예산부서별 예산편성
H9: 연간예산편성(당초) | N9: 연간예산편성현황 (종합) | T9: 예산현황 조회 (월) | Z9: 예산현황 조회 (연간) | AF9: 예산조정신청 (등록) | AL9: 예산조정신청 (현황) | AR9: 예산조정신청 (편성)
H11: 적용연도 | K11: 2018 | O11: 예산부서 | R11: XXXXXX | U11: + | V11: 수출영업1-1팀 | AC11: 조회 | AF11: 저장 | AI11: * 천원단위 입력
H14: 예산부서 | Q14: 예산세목 | AB14: 월별 예산편성 현황
H15: PXXX | J15: 수출영업1-1팀 | N15: ▤ | Q15: 코드 | T15: 세목명 | AB15: 1월 | AE15: 2월 | AH15: 3월 | AK15: 4월 | AN15: 5월 | AQ15: 6월 | AT15: 7월 | AW15: 8월 | AZ15: 9월 | BC15: 10월 | BF15: 11월 | BI15: 12월 | BL15: 연간계
H16: XXXX | J16: 수출영업1-1팀 | P16: □ | Q16: XXXXX | T16: 조직관리비
H17: XXXX | J17: 수출영업1-2팀 | P17: □ | Q17: XXXXX | T17: 회의비식대
H18: XXXX | J18: 수출영업본부장 | P18: □ | Q18: XXXXX | T18: 국내출장숙박비
H19: XXXX | J19: 수출영업1부문장 | P19: □ | Q19: XXXXX | T19: 국내출장일비
H20: XXXX | J20: 수출영업2부문장 | P20: □ | Q20: XXXXX | T20: 국내출장기타경비
P21: □ | Q21: XXXXX | T21: 해외출장항공료
P22: □ | Q22: XXXXX | T22: 해외출장숙박비
P23: □ | Q23: XXXXX | T23: 해외출장일비
P24: □ | Q24: XXXXX | T24: 해외출장기타경비
G26: * 연간예산편성은 기중 마감이 진행되지 않은 달의 예산은 수정가능 (단, 마감이후 기간소급분 수정 불가)
G27: * Profit center 는 예산편성 대상부서 X
H30: 연간예산편성(당초) | N30: 연간예산편성현황 (종합) | T30: 예산현황 조회 (월) | Z30: 예산현황 조회 (연간) | AF30: 예산조정신청 (등록) | AL30: 예산조정신청 (현황) | AR30: 예산조정신청 (편성)
H32: 적용연도 | K32: 2018 | O32: 예산부서 | R32: XXXXXX | U32: + | V32: 수출영업1-1팀 | AC32: 조회 | AF32: 임의예산편성 저장
H35: 예산부서 | Q35: 예산세목 | Z35: 예산 구분 | AB35: 월별 예산편성 현황 (종합-조정분 반영)
H36: PXXX | J36: 수출영업1-1팀 | N36: ▤ | Q36: 코드 | T36: 세목명 | AB36: 1월 | AE36: 2월 | AH36: 3월 | AK36: 4월 | AN36: 5월 | AQ36: 6월 | AT36: 7월 | AW36: 8월 | AZ36: 9월 | BC36: 10월 | BF36: 11월 | BI36: 12월 | BL36: 연간계 | BO36: ▤
H37: XXXX | J37: 수출영업1-1팀 | P37: □ | Q37: XXXXX | T37: 조직관리비 | Z37: 당초
H38: XXXX | J38: 수출영업1-2팀 | Z38: 추가
H39: XXXX | J39: 수출영업본부장 | Z39: 임의
H40: XXXX | J40: 수출영업1부문장 | Z40: 소계
H41: XXXX | J41: 수출영업2부문장 | P41: □ | Q41: XXXXX | T41: 회의비식대 | Z41: 당초
Z42: 추가
Z43: 임의
Z44: 소계
P45: □ | Q45: XXXXX | T45: 국내출장숙박비 | Z45: 당초
Z46: 추가
Z47: 임의
Z48: 소계
G50: * 예산편성된 Data 만 조회/임의예산편성하는 메뉴임 (예산 잔액이월, 선집행 등 예산집행과 관련된 Data 제외)
G51: * 예산구분 정의
G52: ① 당초(예산) : 연간예산편성(당초) 메뉴에서 사업계획시 부서별/예산세목별/월별로 편성된 예산 (기중 수정은 연간 Total 금액내에서만 조정 가능)
G53: ② 추가(예산) : 현업 예산조정신청 및 승인 Process 를 통해 기중 추가예산 승인된 예산금액
G54: ③ 임의(예산) : 경영관리팀 담당자 임의로 특정목적을 위해 편성된 예산 → 임의예산을 '부서별-예산세목별-임의예산' 항목 월별 금액 입력후, '임의예산편성 저장' 시 해당 예산편성 반영 (단, 연간예산편성(당초) 와는 별개임)
F57: ■ | G57: 예산현황조회
H60: 연간예산편성(당초) | N60: 연간예산편성현황 (종합) | T60: 예산현황 조회 (월) | Z60: 예산현황 조회 (연간) | AF60: 예산조정신청 (등록) | AL60: 예산조정신청 (현황) | AR60: 예산조정신청 (편성)
...

Sheet 최초안
G2: *** 생산사전원가 세부정보 Tab 필요, 니트 Artwork / 쉐이드밴드 컨펌과정 및 코멘트 필요, 스웨터팀 진척율 시트참고, 팬츠팀 업체스케쥴 시트 참고
G3: *** 예상사전원가, 생산사전원가 입력일 정보 필요, 각 TAB 별 진행 History comments 입력기능 필요
G4: *** 제약사항 : 등록방법, 등록기준, 등록Depth, 등록범위, 용어개념화 등 체계화 미흡 (사전 BPR 작업 필요)
G6: 스타일정보
H8: Style no. | L8: 차수 | N8: File no. | R8: 스케치 | T8: 시즌 | W8: 브랜드 | AD8: COLOR | AG8: 기획수량 | AK8: 담당자
W10: 상위 | Y10: 하위 | AA10: 복종 | AK10: Design | AN10: MD | AQ10: 소싱 | AT10: Fabric
G11: □ | H11: MSZ5TS1001 | L11: A | N11: TO19TT7001 | R11: [+] | T11: SP | W11: TT | Y11: MS | AA11: JUMPER | AD11: 5 | AF11: [+] | AG11: 1500 | AJ11: [+] | AK11: O OO | AN11: O OO | AQ11: O OO | AT11: O OO
G12: □ | R12: [+] | AF12: [+] | AJ12: [+]
G13: □ | R13: [+] | AF13: [+] | AJ13: [+]
G14: □ | R14: [+] | AF14: [+] | AJ14: [+]
S15: ↑ | T15: 제품이미지 | AF15: ↑ | AG15: 세부컬러 | AJ15: ↑ | AK15: 칼라/사이즈별 수량정보
L17: 소싱정보
H19: Style no. | L19: 차수 | N19: 소싱팀 | Q19: 소싱형태 | U19: 원산지/무역정보 | AE19: 소싱업체 | AM19: 작지정보 | AS19: 납기일 (In-DC)
U21: 원산지 | X21: HS Code | AB21: 무역협정 | AE21: 결제업체 | AI21: 봉제공장 | AM21: 수취일 | AP21: 확정일
G22: □ | H22: MSZ5TS1001 | L22: A | N22: 니트1팀 | Q22: 임가공 | U22: 미얀마 | X22: 6109.10.1000 | AB22: GSP | AE22: SHINSUNG Int'l | AI22: SSTS#1 | AM22: 2018-06-14 | AP22: 2018-07-11 | AS22: 43419 | AV22: [+]
G23: □ | AV23: [+]
G24: □ | AV24: [+]
G25: □ | AV25: [+]
G26: * 작지정보 별도표기 여부 문의 | AS26: ↑ | AT26: 최근기준 | AV26: ↑ | AW26: 납기일 변경 History
Q28: 단가정보
H30: Style no. | L30: 차수 | N30: 기획수량 | Q30: PCS당 | AV30: Amount (기획수량 기준) | BG30: PCS당
Q31: Retail Price | W31: 사전원가 | AI31: 사후원가 (입고평균) | AL31: 생산 배수 | BG31: FOB (USD)
Q32: 예상 | T32: 확정 | W32: MD협의 | Z32: 예상 | AC32: 생산(최초) | AF32: 생산(최종) | AL32: MD협의 | AN32: 예상 | AP32: 사전(초) | AR32: 사전(종) | AT32: 사후 | AV32: Retail Price | AY32: 사전COGM | BB32: 사후COGM | BG32: 예상 | BJ32: 확정
G33: □ | H33: MSZ5TS1001 | L33: A | N33: 1500 | Q33: 199900 | T33: 199000 | W33: 50000 | Z33: 49000 | AC33: 49200 | AF33: 48000 | AI33: 48500 | AL33: =IF($T33<>0,($T33/1.1)/W33,($Q33/1.1)/W33) -> 3.6181818 | AN33: =IF($T33<>0,($T33/1.1)/Z33,($Q33/1.1)/Z33) -> 3.6920223 | AP33: =IF($T33<>0,($T33/1.1)/AC33,($Q33/1.1)/AC33) -> 3.677014 | AR33: =IF($T33<>0,($T33/1.1)/AF33,($Q33/1.1)/AF33) -> 3.7689394 | AT33: =IF(AI33=0,0,IF($T33<>0,($T33/1.1)/AI33,($Q33/1.1)/AI33)) -> 3.7300843 | AV33: =IF($T33<>0,$N33*T33,$N33*Q33) -> 298500000 | AY33: =IF($AF33<>0,$N33*AF33,$N33*Z33) -> 72000000 | BB33: =IF($AI33=0,0,AI33*N33) -> 72750000
G34: □
G35: □
G36: □
G37: * 입고원가 (셔츠팀 기준 DDP Price) 는 입고종결처리전 현업에서 별도 정확한 산출없이 추정 불가. 따라서, 시스템 기준 입고원가 끌어와야 함 | BG37: ↑ 시스템 등록정보 있는지 확인필요
G38: * PCS당 사전원가 USD기준정보 필요한지 여부 체크
G39: * 빨강색 사후원가 관련 필드 삭제 or 별도조회 여부 체크
W40: 자재정보
H42: Style no. | L42: 차수 | O42: 원자재 | BT42: 부자재 | CE42: 원자재
O43: SPEC | AE43: 거래처 | AL43: 원단발주 | AU43: 제검사 | BI43: 원단입고 | BR43: SHADE BAND | BT43: 원단발주 | CE43: 요척
O44: 혼용율 | V44: DESCRIPTION | AE44: 업체명 | AI44: CO | AL44: 접수일 | AO44: 발주일 | AR44: 납기일 | AU44: BT cfm | AY44: 원단 cfm | BC44: APP YDS | BF44: KC/이화학 | BI44: 운송유형 | BL44: ETD | BO44: ETA | BT44: 발주일 | BW44: ETD | BZ44: ETA | CE44: 개발 | CG44: 공장
G45: □ | H45: MSZ5TS1001 | L45: A | N45: ▣ | O45: 49%WOOL 49%POLYESTER 2%POLYURETHANE | V45: 2/90*1/50PU 280G/M 49%WOOL 49%POLYESTER 2%POLYURETHANE 57" | AE45: SINO(AOYANG) | AI45: 중국 | AL45: 2018-08-01 | AO45: 2018-08-04 | AR45: 2018-09-01 | AU45: 2018-09-08 | AX45: [+] | AY45: 2018-09-08 | BB45: [+] | BC45: 2018-09-09 | BF45: 인열 불합격 | BI45: VESSEL | BL45: 2018-09-08 | BO45: 2018-09-09 | BR45: [+] | BT45: 2018-08-04 | BW45: 2018-09-01 | BZ45: 2018-09-01
G46: □ | AX46: [+] | BB46: [+] | BR46: [+]
G47: □ | AX47: [+] | BB47: [+] | BR47: [+]
G48: □ | AX48: [+] | BB48: [+] | BR48: [+]
G49: * 원단 Main 한 종류만 정보를 표기해도 무방한지 체크 | N49: ↑스타일 자재정보등록 조회 | V49: ↑ | W49: Body (Main) 기준으로 조회 | BI49: ↑ 시스템 등록정보 유무 확인필요 | BT49: ↑ 시스템 등록정보 유무 확인필요 | CE49: ↑ 현재 Tab 필요여부 문의
G50: * 요척합의일 필요한지 문의 | BI50: ↑ 원단 분할선적시 처리 방법 문의
...

Sheet 제품유형분류
B3: 카테고리(전산) | D3: 카테고리 | F3: 대품종 | H3: 품종 | J3: 프로그램
B5: 01_KNIT | D5: Bags | F5: SET-UP | H5: BOTTOM | J5: 5-Pocket Pants
B6: 02_SHIRTS | D6: Beach Wear | F6: 가죽&FUR | H6: Short 스커트 | J6: 5-Pocket Shorts
B7: 03_SWEATER | D7: Belt | F7: 기타 | H7: TOP | J7: 7L-Shirts
B8: 04_PANTS | D8: Cardigan | F8: 니트 셔츠 | H8: Turtle | J8: 7L-Tees
B9: 05_DENIM | D9: Coat | F9: 데님 | H9: T-에리 | J9: Active Cardigan
B10: 06_OUTER | D10: Collar Tees | F10: 사파리 | H10: VEST | J10: Active Collar Tees
B11: 07_DRESS/SKIRTS | D11: Cooling Tees | F11: 소품 | H11: V-넥 | J11: Active Hoodie
B12: 08_UNDER | D12: Dress Shirts | F12: 수트 | H12: 가방 | J12: Active Hoodie Cardigan
B13: 09_SUITS | D13: Glove | F13: 스웨터 | H13: 가죽사파리 | J13: Active MTM
B14: 10_ACC/ETC | D14: Hat/Cap | F14: 스커트 | H14: 가죽자켓 | J14: Active Shorts
D15: HomeWear | F15: 언더웨어 | H15: 가죽점퍼 | J15: Active Sweat Pants
D16: Hoodie Cardigan | F16: 우븐 셔츠 | H16: 기타 | J16: Active Tanks
D17: Hoodies | F17: 원피스 | H17: 니트반바지 | J17: Active Tees
D18: InnerWear | F18: 자켓 | H18: 니트팬츠 | J18: Active Vest
D19: Jacket | F19: 점퍼 | H19: 다운점퍼 | J19: A-Line One-Piece
D20: Jeans | F20: 조끼 | H20: 더블재킷 | J20: A-Line Skirt
D21: Jumper | F21: 코트 | H21: 더블코트 | J21: Back Pack
D22: Jumpsuit | F22: 팬츠 | H22: 데님반바지 | J22: Band Pants
D23: Leather/Fur Jacket | H23: 데님셔츠 | J23: Banding Shorts
D24: Leggings | H24: 데님스커트 | J24: Basic Jeans
D25: MTM | H25: 데님자켓 | J25: Basic Tanks
D26: Muffler | H26: 데님팬츠 | J26: Basic Tees
D27: Neck-Tie | H27: 드레스셔츠 | J27: Beach Bottom
D28: One-Piece | H28: 라운드 | J28: Beach Outer
D29: Other Accessories | H29: 라운드(V넥 등) | J29: Beach Top
D30: Other UnderWear | H30: 라운지 반바지 | J30: Belt
D31: Shirts | H31: 라운지 원피스 | J31: Blazer
D32: Shoes | H32: 라운지 후드집업 | J32: Blouse
D33: Shorts | H33: 라운지상의 | J33: BOA Cardigan
D34: Skirts | H34: 라운지하의 | J34: BOA Hoodie Cardigan
... D47: Woven Pants | H47: 셔츠형 | J47: Check Suit Vest
H48: 수트조끼 | J48: Chino Pants
H49: 수트팬츠 | J49: Chino Shorts
H50: 스커트 | J50: Collabo-Tees
H51: 시계 | J51: Cool-Air
H52: 신발 | J52: Corduroy Pants
H53: 싱글재킷 | J53: Corduroy Shirts
H54: 싱글코트 | J54: Denim Jacket
H55: 양말 | J55: Denim Jeggings
...

Sheet 팀별관리양식
C4: 아우터팀 | E4: 제품기획 | P4: 작지 완성도 | R4: 오더 관리 | AF4: FABRIC | AT4: PRODUCTIOIN | BE4: SHIPMENT SCHEDULE | BK4: 입고 정보 | BM4: 주차별 입고 예상 스케줄
E5: NO | F5: 생산팀 | G5: 생산담당자 | H5: SEASON | I5: LINE | J5: ITEM | K5: STYLE NO | L5: 생산차수 | M5: 구분 | N5: COLOR | O5: Q'TY | P5: 작지 수취일 | Q5: 퀄러티확정일 | R5: 납기 | S5: 원가정보 | Z5: 거래형태 | AA5: 생산처 | AB5: 생산국 | AC5: 공장명/업체명 | AD5: 혼용률 | AE5: 원단구분 (우븐/니트) | AF5: DESCRIPTION | AG5: 업체 | AH5: FAB CO | AI5: 원단발주서 | AM5: BT | AN5: 원단컨펌 | AO5: APP YDS | AP5: KC/이화학 TEST(유/무) | AR5: 원단입고 | AT5: APP | AW5: FPP | AY5: PLAN | AZ5: CUTTING | BA5: SEWING | BC5: FINAL INSPECTION REPORT | BD5: 수납 | BE5: ETD | BF5: ETA | BG5: SHIP MODE | BH5: Q'TY | BI5: 예상 IN-DC | BJ5: REMARK | BK5: 1차 입고일자 | BL5: 입고 누적수량 | BM5: 1차 입고 | BO5: 2차 입고 | BQ5: 3차 입고 | BS5: 4차 입고 | BU5: 잔량 입고
S6: 사사전원가 | T6: 사전원가 | U6: 예상판매가(원) | V6: 결정판매가(원) | W6: 생산원가합 | X6: 판매가합 | Y6: 실배수 (V-) | AI6: 접수일 | AJ6: 발주일 | AK6: 납기 | AL6: 최종납기 | AM6: CFM | AN6: CFM | AQ6: ETD (최초선적) | AR6: ETA | AS6: SHIP MODE | AT6: 1차 QC접수 | AU6: 2차 QC접수 | AV6: CFM | AW6: FPP 접수 | AX6: CFM | AY6: 투입계획 | AZ6: 실제일자 | BA6: START (실제일자) | BB6: FININSH (실제일자) | BD6: CFM | BM6: 예정 일자 | BN6: 예상 수량 | BO6: 예정 일자 | BP6: 예상 수량 | BQ6: 예정 일자 | BR6: 예상 수량 | BS6: 예정 일자 | BT6: 예상 수량 | BU6: 예정 일자 | BV6: 예상 수량
E7: 1 | F7: 아우터팀 | G7: 유승모 | H7: 봄 | I7: AB | J7: JUMPER | K7: ABZ1JP1101 | L7: A | N7: 2 | O7: 2500 | P7: 43265 | R7: 43442 | S7: 36800 | U7: 199900 | W7: 92000000 | X7: 499750000 | Y7: 4.9382411 | Z7: 임가공 | AA7: 아우터팀 | AB7: 미얀마 | AC7: SSTS#1 | AD7: 100%POLYESTER | AE7: 우븐 | AF7: P50D DTY * P50D DTY 168*114 WR TPU LAMI 100%POLYESTER 55" | AG7: 예진 | AH7: 국내 | AI7: 43269 | AJ7: 43269 | AK7: 43340 | AL7: 43342 | AM7: 43288 | AN7: 43306 | AO7: 43308 | AP7: 인열 불합격 | AQ7: 43342 | AR7: 43363 | AS7: VESSEL | AT7: 43322 | AU7: 43339 | AV7: 43341
C9: 정장팀 | E9: 제품기획 | P9: 작지 완성도 | R9: 오더 관리 | AF9: FABRIC | AT9: PRODUCTIOIN | BE9: SHIPMENT SCHEDULE | BK9: 입고 정보 | BM9: 주차별 입고 예상 스케줄
E10: NO | F10: 생산팀 | G10: 생산담당자 | H10: SEASON | I10: LINE | J10: ITEM | K10: STYLE NO | L10: 생산차수 | M10: 구분 | N10: COLOR | O10: Q'TY | P10: 작지 수취일 | Q10: 퀄러티확정일 | R10: 납기 | S10: 원가정보 | Z10: 거래형태 | AA10: 생산처 | AB10: 생산국 | AC10: 공장명/업체명 | AD10: 혼용률 | AE10: 원단구분 (우븐/니트) | AF10: DESCRIPTION | AG10: 업체 | AH10: FAB CO | AI10: 원단발주서 | AM10: BT | AN10: 원단컨펌 | AO10: APP YDS | AP10: KC/이화학 TEST(유/무) | AR10: 원단입고 | AT10: APP | AW10: FPP | AY10: PLAN | AZ10: CUTTING | BA10: SEWING | BC10: FINAL INSPECTION REPORT | BD10: 수납 | BE10: ETD | BF10: ETA | BG10: SHIP MODE | BH10: Q'TY | BI10: 예상 IN-DC | BJ10: REMARK | BK10: 1차 입고일자 | BL10: 입고 누적수량 | BM10: 1차 입고 | BO10: 2차 입고 | BQ10: 3차 입고 | BS10: 4차 입고 | BU10: 잔량 입고
S11: 사사전원가 | T11: 사전원가 | U11: 예상판매가(원) | V11: 결정판매가(원) | W11: 생산원가합 | X11: 판매가합 | Y11: 실배수 (V-) | AI11: 접수일 | AJ11: 발주일 | AK11: 납기 | AL11: 최종납기 | AM11: CFM | AN11: CFM | AQ11: ETD (최초선적) | AR11: ETA | AS11: SHIP MODE | AT11: 1차 QC접수 | AU11: 2차 QC접수 | AV11: CFM | AW11: FPP 접수 | AX11: CFM | AY11: 투입계획 | AZ11: 실제일자 | BA11: START (실제일자) | BB11: FININSH (실제일자) | BD11: CFM | BM11: 예정 일자 | BN11: 예상 수량 | BO11: 예정 일자 | BP11: 예상 수량 | BQ11: 예정 일자 | BR11: 예상 수량 | BS11: 예정 일자 | BT11: 예상 수량 | BU11: 예정 일자 | BV11: 예상 수량 | BW11: 요척합의
E12: 1 | F12: 정장팀 | G12: 손지선 | H12: 사계절 | I12: AB | J12: SUIT상 | K12: ABZ5SB1201 | L12: A | M12: SOLID | N12: 2 | O12: 8500 | P12: 43292 | Q12: 43266 | R12: 43419 | S12: 37524.4 | U12: 199000 | W12: 318957400 | X12: 1691500000 | Y12: 4.8211055 | Z12: CMT | AA12: 정장팀 | AB12: 베트남 | AC12: 블루컴퍼니 | AD12: 49%WOOL 49%POLYESTER 2%POLYURETHANE | AE12: 우븐 | AF12: 2/90*1/50PU 280G/M 49%WOOL 49%POLYESTER 2%POLYURETHANE 57" | AG12: SINO(AOYANG) | AH12: 중국 | AI12: 43259 | AJ12: 43259 | AK12: 43358
E13: 2 | F13: 정장팀 | G13: 손지선 | H13: 사계절 | I13: AB | J13: SUIT하 | K13: ABZ5SP1201 | L13: A | M13: SOLID | N13: 2 | O13: 10625 | P13: 43292 | Q13: 43266 | R13: 43419 | S13: 19369.65 | U13: 99000 | W13: 2.0580253e+08 | X13: 1051875000 | Y13: 4.6464443 | Z13: CMT | AA13: 정장팀 | AB13: 베트남 | AC13: 블루컴퍼니 | AD13: 49%WOOL 49%POLYESTER 2%POLYURETHANE | AE13: 우븐 | AF13: 2/90*1/50PU 280G/M 49%WOOL 49%POLYESTER 2%POLYURETHANE 57" | AG13: SINO(AOYANG) | AH13: 중국 | AI13: 43259 | AJ13: 43259 | AK13: 43358
C16: 팬츠팀 | S16: 오더 진행 | V16: 생산원가 | AC16: 부자재 | AE16: 원단/부자재 현황
E17: BRAND | F17: 품번 | G17: 차수 | H17: 복종 | I17: 파일번호 | J17: 담당 디자이너 | K17: DESCRIPTION | L17: W/S | M17: ORDER QTY | N17: COL QTY | O17: COL | P17: 작지 접수 | Q17: 가먼트 납기(INDC) | R17: Ex Fac | S17: 생산형태 | T17: 생산처 | U17: FAC. | V17: 사사전원가 | W17: 사전원가 | X17: 예판가 | Y17: 확정 판매가 | Z17: 사전원가 합 | AA17: 생산 원가 합 | AB17: MU | AC17: ACC 발주일 | AD17: ACC 선적일 | AE17: 원단납기 | AF17: 원단 요청 납기 | AG17: 원단업체 | AH17: 원단SPEC | AI17: 원단가 | AJ17: BT | AK17: MAIN FABRIC CFM | AL17: 원단 REPROT | AM17: ETD FAB | AN17: QC | AO17: FPP | AP17: APPROVED FPP 발송 일 | AQ17: 재단 시작일 | AR17: 봉제 투입일 | AS17: 봉제 완료일 | AT17: INLINE & GARMENT TEST | AU17: SHIPPING SAMPLE | AV17: ETD | AW17: ETA | AX17: INDC | AY17: 비고
E18: TOPTEN | F18: MSZ1PP2002 | G18: A | H18: 1PP | J18: 김정은 | K18: W)CTN SEMI WIDE CASUAL | M18: 2300 | O18: BE | P18: 43278 | Q18: 43467 | S18: 완사입 | T18: 베트남 | U18: 나인 | V18: 10000 | X18: 39900 | Z18: 23000000 | AB18: 3.6272727 | AE18: 43308 | AF18: 43363 | AG18: 나인 | AH18: 나인)VJSS-16798 7*7 68*68 57/58" 373GSM | AM18: 0 | AN18: 7/27 OK | AO18: 0
C20: 니트팀 | E20: ORDER ISSUE | M20: 스타일 정보 | AC20: DETAIL DESCRIPTION | AI20: ARTWORK | AK20: 발주 | AM20: QC | AR20: 생산진행 | BC20: 원가정보 | BJ20: CMPH | BO20: BT CFM | BP20: EMB | BQ20: PRINT | BR20: F/SO
M21: 63 | P21: 224 | Q21: 800300 | AW21: 날짜값만입력 | BC21: 21100 | BD21: 0 | BE21: 83600 | BF21: 0 | BG21: 1227500000 | BH21: 4327500000 | BI21: 3.204962
E22: NO | F22: 디자이너 | G22: 담당자 | H22: 작지수령 | I22: 작지확정 | J22: 시즌 | K22: 브랜드 | L22: ORDER구분 | M22: SKETCH | N22: ST NO | O22: FILE NO. | P22: COL | Q22: Q'TY | R22: 최종납기 | S22: 납기변경내역 | T22: 1ST IN | U22: 1ST Q'TY | V22: 2ST IN | W22: 2ST Q'TY | X22: 3ST IN | Y22: 3ST Q'TY | Z22: 생산국 | AA22: 생산처 | AB22: REMARK | AC22: F.담당 | AD22: F.MILL | AE22: FBR DESC. | AF22: 제품 혼용율 | AG22: GARMENT DESC | AH22: HS CODE | AI22: 나염 | AJ22: 자수 | AK22: 원단발주 | AL22: 부자재발주 | AM22: QC1 | AN22: QC2 | AO22: QC3 | AP22: QC CFM | AQ22: REMARK | AR22: FPP발송 | AS22: FPP접수 | AT22: FPP CFM | AU22: REMARK | AV22: 요척합의 | AW22: FAB ETD | AX22: 원단세부 | AY22: 투입 | AZ22: 종결 | BA22: REMARK | BB22: TOP | BC22: 사사전원가 | BD22: 사전원가 | BE22: 예판가 | BF22: 결판가 | BG22: 원가합 | BH22: 판가합 | BI22: 배수 | BJ22: CM(P) | BK22: H | BL22: P | BM22: PH2 | BN22: FOB
E23: 1 | F23: 홍나영 | G23: 조하나 | H23: 43278 | I23: 43278 | J23: 사계절(SS) | K23: TT | L23: 메인 | M23: 1 | N23: MSZ5TS3901A | O23: TO19TT6007 | P23: 8 | Q23: 30000 | R23: 43480 | S23: 0 | T23: 0 | U23: 0 | V23: 0 | W23: 0 | X23: 0 | Y23: 0 | Z23: 미얀마 | AA23: MYM | AB23: 임가공 | AC23: 김용옥 | AD23: 국내임가공 | AE23: CM26'S/1 SINGLE JERSEY WITH COMPACT + ENZYME (175G) | AF23: C100 | AG23: MEN'S T-SHIRTS | AH23: 6109.10.1000 | AI23: X | AJ23: X | AK23: 43278 | AL23: 43298 | AM23: 43298 | AN23: 0 | AO23: 0 | AP23: 43298 | AQ23: 0 | AR23: 0 | AS23: 0 | AT23: 0 | AU23: 0 | AV23: 0 | AW23: 43359 | AX23: SOL 9/16 30% (8040), 9/23 30% (8040), 9/30 40% (13920) MEL 10/7 100% (3200) | AY23: 43427 | AZ23: 43452 | BA23: 37~38 | BB23: 0 | BC23: 3307 | BD23: 0 | BE23: 15900 | BF23: 0 | BG23: 99210000 | BH23: 477000000 | BI23: 4.3708937 | BJ23: 0.48 | BK23: 0.06 | BL23: 0.09 | BM23: 0.01 | BN23: 0
C30: 스웨터팀 | E30: 순번 | F30: 시즌 | G30: 브랜드 | H30: STYLE# | I30: 차수 | J30: PCS | K30: 업체 | L30: 실입고수량 | M30: QUALITY | N30: LAST BT | O30: BT | P30: 원사발주 | Q30: YARN ETA | R30: 1ST QC | S30: 2ND QC | T30: 3RD QC | U30: APP | V30: LINE | W30: FPP | X30: TOP | Y30: INSPECTION | Z30: ETD | AA30: ETA | AB30: IN-DC | AC30: 2nd DELI | AD30: 협의 납기 | AE30: STATUS | AF30: 최초기획납기 | AG30: 거래형태 | AH30: 생산국 | AI30: 혼용율 | AJ30: 실제혼용율 | AK30: 번수 | AL30: GG | AM30: PLY | AN30: 중량 | AO30: ASSORT | AP30: 예상원가 | AQ30: 예상판가 | AR30: FOB PRICE | AS30: ETD+45 | AT30: AMOUNT | AU30: FACTORY | AV30: DETAIL YARN SPEC | AW30: 입고율 | AX30: 기획원가 합 | AY30: 기획판가 합
E31: 1 | F31: SP | G31: OLZEN | H31: ZOZ1ER1101 | I31: A | J31: 1800 | K31: SANTEX | M31: 43271 | N31: 43283 | O31: 43304 | P31: 43307 | Q31: 43315 | U31: 43300 | V31: 43330 | W31: 43337 | X31: 43427 | Z31: 43434 | AA31: 43439 | AB31: 43441 | AE31: ZOZER002 | AF31: 43446 | AG31: 직LC | AH31: 중국 | AI31: W=100 (COMPACT) | AK31: 30'S/2 | AL31: 12 | AM31: 1 | AN31: 309 | AP31: 19000 | AQ31: 128000 | AT31: 0 | AV31: 30'S/2 12GG 1PLY | AW31: 0 | AX31: 34200000 | AY31: 230400000
AK34: 이 항목들이 TRIM 관련 정보인지 여부 | CV34: 이해불가 | DS34: 이해불가
K35: 작업지시서 워크시트 수령일 | L35: 작업지시서 확정일 | M35: 공장출하일 | N35: 납기일 | Q35: 수량 | R35: 수량 | S35: 수량 | T35: 수량 | U35: 수량 | V35: 수량 | W35: 수량 | X35: 수량 | Y35: 수량 | Z35: 원산지 | AA35: 생산형태 | AB35: 봉제공장 | AD35: 원산지증명 | AF35: 요척 | AG35: YDS당 단가 | AH35: PCS당 원자재 원가 | AI35: 원단 사용 차수 | AK35: 안감 | AL35: 봉사 | AM35: 단추 | AN35: 라벨 | AO35: 기타부자재 | AP35: 팩킹자재 | AQ35: PCS당 부자재 원가 | AV35: 팩킹 핸들링 차지 | AW35: PCS당 CMP 원가 | BC35: 에이션 마진율 | BM35: MD 확정 가격 | BN35: MD 확정 Amt | BO35: MD M/up | BP35: 원단제조업체 | BQ35: 발주일 | BR35: 원단납기일 | BU35: 자재선적 수단 | BV35: 부자재 ETD | BW35: 부자재 ETA | BX35: 생산일정 | BY35: 시직,BT 검사납기 | BZ35: 시직,BT 디자인 1차제출일 | CA35: 1차 컨펌 | CB35: 시직,BT 디자인 2차 제출일 | CC35: 2차 컨펌 | CD35: 시직,BT 디자인 3차 제출일 | CE35: 3차 컨펌 | CF35: 시직,BT 디자인 4차 제출일 | CG35: 4차 컨펌 | CH35: 원단 1차생산분 제출일 | CI35: 원단 1차 컨펌 | CJ35: 원단 2차생산분 제출일 | CK35: 원단 2차 컨펌 | CL35: 원단 3차생산분 제출일 | CM35: 원단 3차 컨펌 | CN35: 샘플야대지 수령일 | CO35: 샘플야대지 디자이너 승인일 | CV35: 승인 원부자재 송부일 | CW35: 원단선적예상일 | CY35: 원단 1차선적예상일 | DG35: 원단 선적수량 | DJ35: 공장요척 | DL35: 요척합의서(공장에서 소싱팀) | DM35: 재단수량 | DR35: 선적샘플 수령일 | ED35: 사전원가 등록일 | EE35: 물류납기 1차 | EF35: 물류납기 2차 | EG35: 물류납기 3차 | EH35: 물류납기 4차 | EI35: 물류입고 총수량 | EL35: 부족수량 비율
C36: 셔츠팀 | E36: No | F36: SLV | G36: FAB PTTN | H36: St. | I36: STYLE NO | K36: W/S RCVD | L36: W/S FIXED DATE | M36: EX-FTY DUE | N36: IN DC DUE DATE | O36: COL | P36: PATTERN / COL | T36: ASSORT | Y36: Q'TY | Z36: GMT ORIGIN | AA36: TYPE OF PRODUCE | AB36: GMT FACTORY (MFG) | AC36: HS CODE | AD36: C/O (PAPER) | AE36: FABRIC DESCRIPTION | AF36: Shell Y.Y | AG36: FABRIC U/P | AH36: FABRIC TOTAL AMT | AI36: CONTRAST (1) | AJ36: CONTRAST (2) | AK36: INTER LINING | AL36: THREAD | AM36: BTTN | AN36: LABEL TAG | AO36: OTHERS | AP36: PACK | AQ36: TRIM TOTAL AMT | AR36: C.M | AS36: G/Wash | AT36: EMB | AU36: Print / Others | AV36: PH (1+2) | AW36: CMP TOTAL AMT | AX36: FOB PRICE | AY36: FOB for EX INFO | AZ36: FREIGHT | BA36: IMPORT TARIFF 5% | BB36: AIR CHARGE | BC36: FOR A.tion (9.44%) | BD36: DDP PRICE | BE36: DDP PRICE (KOR) | BF36: DDP PRICE (E) | BG36: DDP AMOUNT | BH36: RETAIL PRICE (E) | BI36: RETAIL PRICE | BJ36: RETAIL AMOUNT | BK36: M/U (-V) | BL36: M/U (+V) | BM36: MD CFMD PRICE | BN36: MD CFMD AMT | BO36: MD M/U (+V) | BP36: FABRIC ORIGIN /MILL | BQ36: FABRIC ORDERED DATE | BR36: DELIVERY DATE by Fabric team | BS36: FABRIC ETD | BT36: FABRIC ETA | BU36: FABRIC SHIP MODE | BV36: TRIM ETD | BW36: TRIM ETA | BX36: PERIOD of Production | BY36: H/L OR B/T DUE DATE | BZ36: H/L OR B/T SUBMIT | CA36: 1ST CFM | CB36: H/L OR B/T SUBMIT 2ND | CC36: 2ND CFM | CD36: 3RD | CE36: 3RD CFM | CF36: 4TH | CG36: 4TH CFM | CH36: LOT SUBMIT 1ST | CI36: 1ST CFM | CJ36: LOT SUBMIT 2ND | CK36: 2ND CFM | CL36: LOT SUBMIT 3RD | CM36: 3RD CFM | CN36: S/Y RCVD | CO36: QC APPROVAL DUE DATE | CP36: S/D 1st Q.C | CQ36: 1st Q.C RCVD | CR36: S/D 2nd QC | CS36: 2nd QC RCVD | CT36: S/D 3rd QC | CU36: 3rd QC RCVD | CV36: APPROVAL FINAL PACKAGE SENDING DATE | CW36: FABRIC ETD DUE DATE | CX36: FABRIC ORDER Q'TY | CY36: ETD FABRIC 1ST | CZ36: ETA FABRIC 1ST | DA36: ETD FABRIC 2ND | DB36: ETA FABRIC 2ND | DC36: ETD FABRIC 3RD | DD36: ETA FABRIC 3RD | DE36: ETD FABRIC 4TH | DF36: ETA FABRIC 4TH | DG36: FABRIC SHIPPED TOTAL | DH36: FABRIC BALANCE | DI36: BALANCE RATING | DJ36: FACTORY Y.Y | DK36: BALANCE | DL36: Y.Y AGREEMENT COMMENT | DM36: CUT Q'TY | DN36: CUT BALANCE | DO36: CUT RATING | DP36: FABRIC USAGE | DQ36: FABRIC BALANCE | DR36: SHIPMENT SAMPLE RCVD | DS36: ETD RGN 1st | DT36: ETA PSN 1st | DU36: ETD RGN 2nd | DV36: ETA PSN 2nd | DW36: ETD RGN 3rd | DX36: ETA PSN 3rd | DY36: ETD RGN 4th | DZ36: ETA PSN 4th | EA36: SHPD SUM | EB36: SHIP BAL (CUT) | EC36: SHPD RATING | ED36: ESP-Pre COSTING input date | EE36: INDC 1st | EF36: INDC 2nd | EG36: INDC 3rd | EH36: INDC 4th | EI36: INDC TOTAL | EJ36: INDC BALANCE | EK36: INDC AMOUNT | EL36: RATE SHORTAGE OVERAGE | EM36: SHORTAGE COMMENT
E37: 1 | F37: L | G37: SOLID | H37: BLZ1WD1001A | I37: BLZ1WD1001 | J37: A | K37: 43277 | L37: 43286 | M37: 43465 | N37: 43470 | O37: 3 | R37: <90> | S37: <95> | T37: <100> | U37: <105> | V37: <110> | X37: sub | Y37: 8500 | Z37: 미얀마 | AA37: 임가공 | AB37: SSTS#3 | AC37: 6205.20.0000 | AD37: GSP CO | AE37: COTTON 61 POLYESTER 34 POLYURETHANE 5 | AF37: 1.6423529 | AG37: 2.2566372 | AH37: 3.7061947 | AK37: 0.35 | AL37: 0.066371681 | AM37: 0.13274336 | AN37: 0.23893805 | AO37: 0.022123894 | AP37: 0.145 | AQ37: 0.95517699 | AR37: 1.87 | AV37: 0.18 | AW37: 2.05 | AX37: 6.7113717 | AY37: 6.9613717 | AZ37: 0.16778429 | BB37: 0 | BD37: 6.879156 | BE37: 7773.4462 | BF37: 7888 | BG37: 66074293 | BH37: 74000 | BI37: 74000 | BJ37: 629000000 | BK37: 9.5195873 | BL37: 8.6541702 | BM37: 7902 | BN37: 67167000 | BO37: 8.5133798 | BP37: KOREA | BQ37: 43263 | BR37: 43419 | BS37: 43419 | BT37: 43429 | BU37: AIR | BV37: 43290 | BW37: 43320 | BX37: 26 | BY37: 43330 | BZ37: 43278 | CA37: 0 | CB37: 43286 | CC37: 0 | CD37: 43290 | CE37: 43293 | CF37: 0 | CG37: 0 | CH37: 43299 | CI37: 43307 | CJ37: 0 | CK37: 0 | CL37: 0 | CM37: 0 | CN37: 43299 | CO37: 43415 | CP37: 43290 | CQ37: 43300 | CR37: 0 | CS37: 0 | CT37: 0 | CU37: 0 | CV37: 43307 | CW37: 43390 | CX37: 13960 | CY37: 43313 | CZ37: 43314 | DG37: 14047.5 | DH37: 87.5 | DI37: 0.0062679083 | DJ37: 43322 | DM37: 0 | DO37: 0.98094118 | DP37: 0 | DS37: 0 | DT37: 0 | DU37: 0 | DV37: 0 | DW37: 0 | DX37: 0 | DY37: 0 | DZ37: 0 | EA37: 0 | EC37: 0 | ED37: 0 | EE37: 0 | EF37: 0 | EG37: 0 | EH37: 0 | EI37: 0 | EJ37: -8500 | EK37: 0
H38: SEMI WIDE | I38: TY19AZ0001 | L38: 아소트전달 | O38: BK | P38: SOLID | T38: 800 | X38: 800 | AE38: CM40*P100D/PU40 148*84 50" TWILL | AF38: 1.65 | AG38: 2.2566372 | AH38: 3.7234513 | AK38: 395.5 | AL38: 75 | AM38: 150 | AN38: 270 | AO38: 25 | AP38: 163.85 | AQ38: 1079.35 | AR38: 2113.1 | AV38: 203.4 | AX38: 7583.85 | BB38: 0 | BH38: 8.6541702 | BP38: 은성 | BV38: 단추 7/9,7/16 | BZ38: 43278 | CA38: 6/29재 | CB38: 43286 | CC38: 43286 | CH38: 43305 | CI38: 43307 | CN38: 43304 | CX38: 1320 | CY38: 1360.25 | DG38: 1360.25 | DH38: 40.25 | DI38: 0.030492424 | DK38: 0 | DL38: W50.5" | DM38: 818 | DN38: 18 | DO38: 0.0225 | DP38: 1349.7 | DQ38: -10.55 | EA38: 0 | EB38: -818 | EC38: -1 | EI38: 0 | EJ38: -800
O39: BL | P39: SOLID | T39: 1200 | X39: 1200 | AF39: 1.65 | AG39: 2.2566372 | AH39: 3.7234513 | BZ39: 43278 | CA39: 6/29재 | CB39: 43286 | CC39: 7/5재 | CD39: 43290 | CE39: 43293 | CH39: 43306 | CI39: 43307 | CN39: 43304 | CX39: 1980 | CY39: 2026.75 | DG39: 2026.75 | DH39: 46.75 | DI39: 0.023611111 | DK39: 0 | DL39: W50.5" | DM39: 1214 | DN39: 14 | DO39: 0.011666667 | DP39: 2003.1 | DQ39: -23.65 | EA39: 0 | EB39: -1214 | EC39: -1 | EI39: 0 | EJ39: -1200
O40: WT | P40: SOLID | T40: 6500 | X40: 6500 | AF40: 1.64 | AG40: 2.2566372 | AH40: 3.700885 | BZ40: 43278 | CA40: 43280 | CH40: 43299 | CI40: 43301 | CN40: 43299 | CX40: 10660 | CZ40: 10660.5 | DG40: 10660.5 | DH40: 0.5 | DI40: 4.6904315e-05 | DK40: -0.03 | DL40: W49.75" | DM40: 6306 | DN40: -194 | DO40: -0.029846154 | DP40: 10531.02 | DQ40: -129.48 | EA40: 0 | EB40: -6306 | EC40: -1 | EI40: 0 | EJ40: -6500

Sheet 소싱관리팀집계양식
C5: 구분키 | D5: 부서 | E5: 스타일번호 | F5: 기획수량 | G5: 제조원가 | H5: 판매가 | I5: 생산형태 | J5: 생산국 | K5: 생산처 | L5: 납기 | M5: 원단CFM | N5: APP | O5: FPP | P5: CUTTING | Q5: ETD | R5: 입고 | S5: SEASON

Sheet 관리현황집계
L3: 아우터팀 | M3: 정장팀 | N3: 셔츠팀 | O3: 팬츠팀 | P3: 니트팀 | Q3: 스웨터팀
F4: 스타일정보 | G4: Style no.
G5: File no.
G6: 스케치 (Image)
G7: 생산차수
G8: 시즌
G9: 브랜드
G10: 브랜드라인
G11: 복종(ITEM)
G12: COLOR
H13: 칼라수량 합계관리
H14: 칼러수량 개별관리
I15: SOLID
I16: STRIPE
G17: 기획수량
H18: 총수량 관리
H19: 사이즈별 수량 관리
H20: 사이즈/칼라별 수량 관리
G21: *누적입고수량
G22: 담당 디자이너
F24: 소싱정보 | G24: 소싱팀
G25: 소싱담당자
G26: 소싱형태
G27: 소싱처
G28: 소싱국가(원산지)
H29: 원산지
H30: HS CODE
H31: 대상 무역협정
G32: 소싱업체정보
H33: 결제업체
H34: 봉제공장
F36: 단가정보 | G36: PCS당
H37: Retail Price
I38: 예상
I39: 확정
H40: COGM
I41: 예상사전원가
I42: 생산사전원가
J43: 최초
J44: 최종
...

Sheet 고려사항
E2: 마감용 Garment 입출고 수불장에 제품대체 해 넣을 수 있는 Logic 넣어야 함 (경영관리팀 향후 과제)
E4: 원단 Spread 시, Length 처리 필드 재정의 필요
D11: *** | E11: 공장요척 및 실요척 구하는 기준 문의 필요
E13: Function별 Set-up 진행계획 수립 필요
E15: 회계용 Ledger 기준 Closing 여부 매월 점검하면서 선적완료 파일에 대한 잔존 원단, 재단물, Garment 관리 Process 마련 필요
E17: 법인별 필수 Report 나 현황물 체크해야 함
E19: 근태기준 BEP 산출 Logic 필요
E21: 부자재 YOKO Material W/H 입출고 기준으로 별도 등록 및 현황 자료 필요

Sheet Cover
AP9: PMS 개발요청서
AP12: (Production Management System)
AP20: 경영기획실
AP22: 2021. 5. 31

Sheet Process
C3: ■ PMS (Production Management System) Process MAP
D6: Process | K6: Material Warehouse | AB6: Cutting | BY6: Sewing | EP6: EXIM | FA6: Garment Stock Warehouse
D8: Depot (수불거점)
D12: Menu & Process
D32: INDEX | K32: * 공통 기초자료 : 생산지표 산정기준 Function별 인원현황, 근무시간, 급여지급내역 | CO32: * 기초자료 : Line별 생산현황, 공장별 공정별 입출고현황, Defect현황 | EP32: * 기초자료 : 제품별 출고현황

Sheet Master
E3: ■ 주요 Master 체계
F5: 1. Organization of Accounting Standards (Nicaragua 예시 - ISTMO, UDN)
F37: 2. IN-OUT Depot & Transaction
I39: IN-OUT Type | P39: Class1 | W39: Class2 | AD39: Class3 | AK39: Depot / Transaction | BC39: 발생여부
I41: Transfer | P41: In-bound | W41: Material W/H | AE41: (N/A) | AL41: Material W/H | AS41: : Material Warehouse | BC41: IN-OUT
W43: Cutting | AE43: (N/A-통합재단) | AL43: C.Fabric W/H | AS43: : Cutting Fabric Warehouse | BC43: IN-OUT
AL44: Spreading & Cutting | BC44: IN-OUT
AL45: C.Bundle W/H | AS45: : Cutting Bundle Warehouse | BC45: IN-OUT
AL46: :
AE47: Factory 1 | AL47: Fac1-C.Fabric W/H | BC47: IN-OUT
AE48: (공장별 재단) | AL48: Fac1-Spreading & Cutting | BC48: IN-OUT
AL49: Fac1-C.Bundle W/H | BC49: IN-OUT
W51: Sewing | AE51: (N/A-단일공장) | AL51: S.Bundle W/H | AS51: : Sewing Bundle Warehouse | BC51: IN-OUT
AL52: Sewing Line | BC52: IN-OUT
AL53: Garment Stock W/H | AS53: : Garment Stock Warehouse | BC53: IN-OUT
AL54: :
AE55: Factory 1 | AL55: Fac1-S.Bundle W/H | BC55: IN-OUT
AL56: Fac1-Sewing Line | BC56: IN-OUT
AL57: Fac1-Garment Stock W/H | BC57: IN-OUT
P61: Out-bound | W61: Sub-contract | AE61: (N/A) | AL61: (외주봉제업체) | AS61: * 업체별 개별등록
AE65: Print | AL65: (부속가공업체) | AS65: * 업체별 개별등록
W66: Sub-processing | AE66: EMB | AL66: (부속가공업체) | AS66: * 업체별 개별등록
AE67: Washing | AL67: (부속가공업체) | AS67: * 업체별 개별등록
I70: Managing | P70: (N/A) | AL70: Net-IN | AS70: * Material W/H 입고 전용 Transaction | BC70: IN
AL72: Sales | AS72: * 자재 및 제품 판매 | BC72: OUT
AL73: Trans SPEC | AS73: * 자재 SPEC (File/Style 변경) 변경 | BC73: IN-OUT
AL74: Trans Location | AS74: * 자재 Location 변경 | BC74: -
AL75: Sample | AS75: * 샘플사용 | BC75: IN-OUT
AL76: Split | AS76: * 하나의 Roll 원단을 2개 이상의 Roll 로 분할 | BC76: IN-OUT
AL77: Disposal | AS77: * 폐기 | BC77: OUT
AL78: Loss | AS78: * 분실/도난 등 | BC78: OUT
AL79: Adjusted | AS79: * 기타 재고조정 | BC79: IN-OUT
F82: 3. 생산관리 INDEX 기초Data 집계용 Function Master
G84: : HR 자료와 생산실적 Data 연계 집계 필요
I86: Class1 | P86: Class2 | W86: Function | AE86: Remark
I88: Sewing Factory | P88: Sewing Line | X88: Line Manager | AE88: * Sewing Line | BF88: 인원, 근무시간, 인건비
I89: (봉제공장) | P89: (생산라인) | X89: Technician | AE89: : 순수 Line / 법인내 공장별 생산성 측정을 위한 기준
X90: Odd-job
P92: Prod. Support | X92: Material W/H | AE92: * Production Support
P93: (생산지원) | X93: Cutting | AE93: - 법인별 공장운영 특성에 따라 통합체계 상이함 원인, 공장별 생산성 측정 Data 로 부적합
...

Sheet 1.M.WH
E2: Ⅰ. MATERIAL WAREHOUSE
F4: ※ System Menu 구성
G6: ◆ Material Warehouse | O6: □ | P6: Material W/H IN - Plan Reg. (Fabric) | AA6: : 자재창고 입고계획 등록
O7: □ | P7: Material W/H IN - Reg. (Fabric) | AA7: : 자재창고 입고 등록 (바코드 및 수기등록)
O8: □ | P8: Material W/H - Trans Location Reg. | AA8: : 자재창고 Location 변경 등록
O9: □ | P9: Material W/H - Trans SPEC Reg. | AA9: : 자재창고 자재 SPEC 변경 등록 (File/Style Info.)
O10: □ | P10: Material W/H - Split Reg. | AA10: : 자재창고 Roll 분리 등록 (1 Roll → XX Roll)
O11: □ | P11: Material W/H OUT - Reg. (Fabric) | AA11: : 자재창고 출고 등록
O12: □ | P12: Fabric Inspection - Reg. | AA12: : 원단 품질검사 등록 (Next Step)
O14: (R) | P14: Material W/H IN-OUT Ledger | AA14: : 월별 자재창고 입출고 현황 (for Accounting)
O15: (R) | P15: Material W/H IN-OUT Status | AA15: : 기간별 자재창고 입출고 현황 (Lot 단위)
O16: (R) | P16: Material W/H Stock Status (by Present) | AA16: : 현재기준 자재창고 재고 현황 (재고수량 및 Location)
O17: (R) | P17: Fabric Inspection Status | AA17: : 원단 품질검사 현황 (Next Step)
O19: ※ 주의사항 : 출고후, 일일 업무마감 전 출고내역 Target Depot 측 입고처리 완료여부 확인 必
F22: 1-1. Material W/H IN - Plan Reg. (Fabric)
G24: : IN-OUT Depot & Transaction - Managing 중, Net-IN (Material W/H IN 전용 Transaction) 입고등록 전, 사전 필수등록 사항
I27: M. W/H IN - Plan Reg | P27: Status
I29: Shipping Status Search | O29: (팝업창)
I31: - Container info.
I32: From | N32: Supplier | S32: TRANSPORT | W32: Container no. | AB32: Con. Size | AE32: ETD | AI32: ETA
I33: KOREA | N33: XXXXXXXXXX | S33: VESSEL | W33: XXXXXXXXXX | AB33: XXX | AE33: YYYY-MM-DD | AI33: YYYY-MM-DD
I35: - Item infomation by Container
I37: ■ | J37: Order | U37: Item | AM37: Status
J38: File no. | N38: Style no. | R38: Part | U38: CODE | X38: Name | AC38: Description | AJ38: Color | AM38: UNIT | AO38: Length | AR38: Weight | AU38: ▤
I39: V | J39: TN19GB8044 | N39: 12345 | R39: BODY | U39: XXXXXXXX | X39: XXXXXXXX | AC39: XXXXXXXXXXXXXXXXX | AJ39: BLK | AM39: YDS | AO39: 200 | AR39: 200
I40: □ | J40: TN19GB8044 | N40: 12345 | R40: BODY | U40: XXXXXXXX | X40: XXXXXXXX | AC40: XXXXXXXXXXXXXXXXX | AJ40: BLK | AM40: KGS | AO40: 100 | AR40: 200
I41: □ | J41: TN19GB8044 | N41: 12345 | R41: BODY | U41: XXXXXXXX | X41: XXXXXXXX | AC41: XXXXXXXXXXXXXXXXX | AJ41: BLK | AM41: LBS | AO41: 100 | AR41: 200
I44: [ Material W/H IN - Plan Reg. (Barcode Creation) ] | AF44: Save & Barcode create | AL44: Delete
I46: (+)Add | L46: (+) COPY & ADD | P46: (-)Del | S46: □ | T46: Select all | AG46: Plan no. | AJ46: XXXXXXXXXX
I48: ■ | J48: Bulk Reg. | Y48: Gross Qty | AH48: Barcode
J49: Lot no. | M49: Roll no. | P49: UNIT | S49: Qty | V49: Width | Y49: UNIT | AB49: Length | AE49: Weight | AN49: ▤
I50: □ | J50: XXX1 | M50: 1 | P50: Roll | R50: ▼ | S50: 1 | V50: 66 | Y50: YDS | AA50: ▼ | AB50: 60 | AE50: - | AH50: XXXXXXXXXXXXXXXXX
I51: □ | J51: XXX2 | M51: 2 | P51: Roll | R51: ▼ | S51: 1 | V51: 66 | Y51: YDS | AA51: ▼ | AB51: 40 | AE51: - | AH51: XXXXXXXXXXXXXXXXX
I52: □ | J52: XXX3 | M52: 3 | P52: Roll | R52: ▼ | S52: 1 | V52: 66 | Y52: YDS | AA52: ▼ | AB52: 100 | AE52: - | AH52: XXXXXXXXXXXXXXXXX
Q55: Total | S55: =S52+S51+S50 -> 3 | AB55: =AB52+AB51+AB50 -> 200 | AE55: -
J57: * 상단 W/H IN Plan Reg. (Barcode Creation) 의 Status 수치와 상기 등록된 Gross Qty 수량 상이할 시, 저장 불가
J60: Shipping Status Search
K62: Destination | O62: NICARAGUA | S62: ▼ | T62: From | W62: - | AA62: ▼ | AM62: Query | AP62: Apply | AT62: ← 이미 Plan 등록 완료된 Container 는 'Apply' 버튼 클릭해도 적용되면 안됨
K64: Transport | O64: VESSEL | S64: ▼ | T64: ETA | W64: YYYY-MM-DD | AA64: ▤ | AB64: ~ | AC64: YYYY-MM-DD | AG64: ▤
K66: Container no. | O66: XXXXXXXXXX | T66: B/L no. | W66: XXXXXXXXXX | AB66: File no. | AE66: XXXXXXXXXX
...

Sheet 2.Cutting
E2: Ⅱ. Spreading & Cutting
F4: ※ System Menu 구성
H6: ◆ Spreading & Cutting | P6: ◆ Cutting Fabric W/H | X6: □ | Y6: C.Fabric W/H IN - Reg. | AO6: : 재단반 원단창고 입고 등록
P7: (C.Fabric W/H) | X7: □ | Y7: C.Fabric W/H - Trans Location Reg. | AO7: : 재단반 원단창고 Location 변경 등록
X8: □ | Y8: C.Fabric W/H - Trans SPEC Reg. | AO8: : 재단반 원단창고 자재 SPEC 변경 등록 (File/Style/Color/Yds Info.)
X9: □ | Y9: C.Fabric W/H - Trans Split Reg. | AO9: : 재단반 원단창고 자재 Split 등록
X10: □ | Y10: C.Fabric W/H OUT - Reg. | AO10: : 재단반 원단창고 출고 등록
X12: (R) | Y12: C.Fabric W/H - IN-OUT Ledger | AO12: : 월별 재단반 원단창고 입출고 현황 (for Accounting)
X13: (R) | Y13: C.Fabric W/H - IN-OUT Status | AO13: : 기간별/누적 재단반 원단창고 입출고 현황
X14: (R) | Y14: C.Fabric W/H - Stock Status (by Present) | AO14: : 현재기준 재단반 원단창고 재고현황 (재고수량 및 Location)
P16: ◆ Spreading & Cutting | X16: □ | Y16: Sub-processing Plan - Reg (by C. Part) | AO16: : File-Style 재단 부위별 부속가공 계획 등록
X17: □ | Y17: Size Ratio by Marker - Reg. | AO17: : Marker Spec 등록
X18: □ | Y18: Spreading & Cutting - Reg. | AO18: : 연단&재단 실적 등록 (Incl.연단실적)
X19: □ | Y19: Sewing Process - Reg. (for Process tag printing) | AO19: : 파일/스타일별 공정등록 (옵션항목)
X20: □ | Y20: Bundle PKG - Reg. | AO20: : Bundle PKG 코드생성
X21: □ | Y21: C. Bundle PKG Setting - Reg. (PKG & IN - Reg.) | AO21: : Bundle PKG 내 Bundle 구성 등록 (옵션항목 : 동시 C.Bundle W/H IN 가능)
X23: (R) | Y23: Cutting Report | AO23: : 기간별 오더대비 재단물 상세현황
P25: ◆ Cutting Bundle W/H | X25: ▶ | Y25: Cutting Bundle IN-OUT
P26: (C.Bundle W/H) | X26: □ | Y26: C.Bundle W/H IN - Reg. (from Cutting) | AK26: (Garment 기준) | AO26: : 재단물 창고 입고 등록 (from 재단반)
X27: □ | Y27: C.Bundle W/H IN - Reg. | AK27: (Garment 기준) | AO27: : 재단물 창고 입고 등록 (재단반 外)
X28: □ | Y28: C.Bundle W/H - Trans Location Reg. | AK28: (Garment 기준) | AO28: : 재단물 창고 Location 변경 등록
X29: □ | Y29: C.Bundle W/H - Trans SPEC Reg. | AK29: (Garment 기준) | AO29: : 재단물 창고 자재 SPEC 변경 등록 (File/Style/color/Qty Info.)
X30: □ | Y30: C.Bundle W/H - Trans Split Reg. | AK30: (Garment 기준) | AO30: : 재단물 창고 자재 Split 등록
X31: □ | Y31: C.Bundle W/H OUT - Reg. | AK31: (Garment 기준) | AO31: : 재단물 창고 출고 등록
X33: (R) | Y33: C.Bundle W/H - IN-OUT Ledger | AK33: (Garment 기준) | AO33: : 월별 재단물 창고 입출고 현황 (for Accounting)
X34: (R) | Y34: C.Bundle W/H - IN-OUT Status | AK34: (Garment 기준) | AO34: : 기간별/누적 재단물 창고 입출고 현황
X35: (R) | Y35: C.Bundle W/H - Stock Status (by Present) | AK35: (Garment 기준) | AO35: : 현재기준 재단물 창고 재고 현황 (수량 및 Location)
X37: ▶ | Y37: Sub-processing IN-OUT
Y38: □ | Z38: Sub-Processing OUT - Reg. | AK38: (Parts 기준) | AO38: : 재단물 부속가공 출고 등록
Y39: □ | Z39: Sub-Processing Return OUT - Reg. | AK39: (Parts 기준) | AO39: : 재단물 부속가공 재출고 등록
Y40: □ | Z40: Sub-Processing IN - Reg. | AK40: (Parts 기준) | AO40: : 재단물 부속가공 입고 등록
X42: (R) | Y42: Sub-processing IN-OUT Status | AO42: : 재단물 부속가공 입출고 현황
F45: 2-1. C.Fabric W/H (Cutting - Fabric Warehouse)
G47: 2-1-1. C.Fabric W/H IN - Reg.
J50: C.Fabric W/H IN - Reg. | Q50: Status
J52: W/H IN Date | N52: YYYY-MM-DD | R52: ▤ | S52: □ | T52: Date Modify | X52: Depot | AA52: C. Fabric W/H | AG52: + | AX52: Query | BA52: SAVE | BD52: Delete
J54: [ W/H IN - Request Search ]
J56: Req. Date | M56: YYYY-MM-DD | Q56: ▤ | R56: ~ | S56: YYYY-MM-DD | W56: ▤ | X56: □ | Y56: Excl. already processed 'IN' | AG56: Source Depot | AK56: Material W/H | AQ56: +
J58: Buyer | M58: XXXXXXXXXX | Q58: ▤ | R58: File no | U58: XXXXXXXXXX | Y58: + | Z58: Style no | AC58: XXXXXXXXXX | AG58: + | AH58: Lot no | AK58: XXXXXXXXXX | AP58: OUT Reg. no | AT58: XXXXXXXXXX | AY58: Barcode | BB58: XXXXXXXXXX
J60: ■ | K60: IN Y/N | M60: OUT Reg Date | Q60: OUT Reg. no | U60: Source Depot | Y60: Order | AJ60: Item | BB60: Bulk Info. | BQ60: Gross Qty | BY60: Barcode
...

Sheet 3.Sewing
E3: Ⅲ. Sewing Line
F5: ※ System Menu 구성
H7: ◆ Sewing Line | O7: ◆ Sewing Bundle W/H | Y7: □ | Z7: S.Bundle W/H IN - Reg. | AM7: : 봉제라인 재단물 창고 입고 등록
O8: (S.Bundle W/H) | Y8: □ | Z8: S.Bundle W/H - Trans Location Reg. | AM8: : 봉제라인 재단물 창고 Location 변경 등록
Y9: □ | Z9: S.Bundle W/H - Trans SPEC Reg. | AM9: : 봉제라인 재단물 창고 재단물 SPEC 변경등록 (File/Style/Color, Bundle PKG, Bundle)
Y10: □ | Z10: S.Bundle W/H - Trans Split Reg. | AM10: : 봉제라인 재단물 창고 재단물 Split 등록
Y11: □ | Z11: S.Bundle W/H OUT - Reg. | AM11: : 봉제라인 재단물 창고 출고 등록
Y13: (R) | Z13: S.Bundle W/H IN-OUT Ledger (by Month) | AM13: : 월별 봉제라인 재단물 창고 입출고 현황 (for Accounting)
Y14: (R) | Z14: S.Bundle W/H IN-OUT Status (by Period) | AM14: : 기간별 봉제라인 재단물 창고 입출고 현황
Y15: (R) | Z15: S.Bundle W/H - Stock Status (Location) | AM15: : 시점별 봉제라인 재단물 창고 재고 현황 (Location)
O17: ◆ Production Management | Y17: ▶ | Z17: Sewing Line Management
Y18: □ | Z18: Production Scedule Management | AM18: : 라인별 생산계획 등록 (대쉬보드 연계)
Y19: □ | Z19: Production Status by line (Monitoring) | AM19: : 시간대별/라인별 생산현황 모니터링
Y20: □ | Z20: Hourly Sewing Record - Reg. (by Line) | AM20: : 시간대별/라인별 생산실적 등록
Y21: □ | Z21: Daily Sewing Record - Reg. (by Line) | AM21: : 일일 라인별 생산실적 등록
Y22: □ | Z22: Line Defect - Reg. | AM22: : 봉제중/후 완전 or 수선가능 불량 등록
Y24: (R) | Z24: Production Report by period (Q'ty) | AM24: : 수량 기준 기간별 생산현황 리포트
Y25: (R) | Z25: Production Report by period (Amt) | AM25: : 금액 기준 기간별 생산현황 리포트
Y26: (R) | Z26: Production Status (Overall) | AM26: : 세부 생산현황 리포트
Y27: (R) | Z27: Production Status by Process | AM27: : 법인 공정별 생산현황 리포트
Y29: ▶ | Z29: Semi Product IN-OUT
Y30: □ | Z30: Semi Product OUT - Reg. | AM30: : 반제품 부속가공 출고 등록
Y31: □ | Z31: Semi Product Return OUT - Reg. | AM31: : 반제품 부속가공 재출고 등록
Y32: □ | Z32: Semi Product IN - Reg. | AM32: : 반제품 부속가공 입고 등록
Y34: (R) | Z34: Semi Product IN-OUT Status | AM34: : 반제품 (부속가공) 입출고 현황
F38: 3-1. Sewing Bundle W/H
I40: [주의] Sewing Bundle W/H 에서는 부속가공 위한 입출고 불가
G42: 3-1-1. S.Bundle W/H IN - Reg.
I44: [주의] In-bound 내 재단물이 아닌 외부봉제업체 작업중 정책변경으로 재단물 입고시, 재단반에서만 재단물 수기 입고처리 가능
J47: S.Bundle W/H IN - Reg. | T47: Status
J49: W/H IN Date | N49: YYYY-MM-DD | R49: ▤ | S49: □ | T49: Date Modify | X49: Depot | AA49: S.Bundle W/H | AG49: + | AY49: Query | BB49: SAVE | BE49: Delete
J52: [ Request Search ]
J54: Source Depot | N54: C.Bundle W/H | T54: + | U54: □ | V54: Incl. data 'IN' already processed
J56: OUT Date | N56: YYYY-MM-DD | R56: ▤ | S56: ~ | T56: YYYY-MM-DD | X56: ▤ | AC56: OUT Reg no. | AG56: XXXXXXXXXX
J58: File no | N58: XXXXXXXXXX | R58: + | T58: Style no | W58: XXXXXXXXXX | AA58: + | AC58: Style Color | AG58: XXXXXXXXXX | AK58: ▼ | AL58: Bundle no. | AP58: XXXXXXXXXX
J60: [ Query details ]
J62: ■ | K62: IN Y/N | M62: OUT Reg. no | Q62: OUT Date | U62: Source Depot | Z62: B.PKG Barcode | AD62: Bundle no. | AH62: Bundle Barcode | AL62: Order | AX62: SIZE | AZ62: Q'ty
AL63: File no. | AP63: Style no. | AS63: Style Color | AZ63: (PCS) | BC63: ▤
J64: V | K64: N | M64: XXXXXXXX | Q64: YYYY-MM-DD | U64: C.Bundle W/H | Z64: AXXXXXXXX1 | AD64: XXXXXXXXX1 | AH64: XXXXXXXX | AL64: TN18TK7043 | AP64: 241657 | AS64: BCVC13(PL106) | AX64: 18M | AZ64: 14
J65: V | K65: N | M65: XXXXXXXX | Q65: YYYY-MM-DD | U65: C.Bundle W/H | Z65: AXXXXXXXX1 | AD65: XXXXXXXXX2 | AH65: XXXXXXXX | AL65: TN18TK7043 | AP65: 241657 | AS65: BCVC13(PL106) | AX65: 4T | AZ65: 14
...

Sheet 3-1.Prod.Plan
D3: 3-2-1. Production Scedule Management
G5: : 당 메뉴는 ESP2 (수출관리시스템) 과 연동 필수
H7: ※ [ESP2] Order Schedule Management
Y10: Order -Reg.
M11: Order Status
K13: Buyer | Q13: OSHKOSH | Z13: + | AC13: Initial reg. | AJ13: YYYY-MM-DD | AR13: Last update | AY13: YYYY-MM-DD | BW13: New | CC13: Delete | CI13: Save | CO13: Print
K16: Reg no. | Q16: TOK-XXXXXXXX | AC16: Prod.D. | AH16: SHWE LIN PAN | AQ16: + | AT16: Order Status | BC16: Fixed | BL16: ▼ | BO16: Person in charge | BZ16: (Eng Name) | CK16: #(Phone Number)
K19: File no. | Q19: TY20OK0011 | AC19: PO no. | AH19: 193897 | AT19: FOB | AX19: @ PCS | BC19: 3.4
K23: Garment Sketch | X23: + | Z23: - | AC23: Style no. | AR23: Delivery / Order Q'ty | BO23: Prod. Schedule | BZ23: - Request - | CK23: - Prod. Plan -
AC26: (Style no.) | AN26: + | AR26: YYYY-MM-DD | BC26: (Order Q'ty) | BK26: + | BO26: Cutting | BZ26: YYYY-MM-DD | CK26: YYYY-MM-DD
AC29: 1J056810 | AN29: - | AR29: 43869 | BC29: 117 | BK29: - | BO29: Sewing | BZ29: YYYY-MM-DD | CK29: YYYY-MM-DD
AC31: 2J056810 | AN31: - | AR31: 43870 | BC31: 890 | BK31: -
AC33: 3J056810 | AN33: - | AR33: 43871 | BC33: 13362 | BK33: -
AN35: - | AR35: 43875 | BC35: 12416 | BK35: -
AN37: - | AR37: 43876 | BC37: 8592 | BK37: -
AN39: - | AR39: 43877 | BC39: 23382 | BK39: -
AN41: - | AR41: 43880 | BC41: 10123 | BK41: -
K43: Garment Description | AN43: - | AR43: 43880 | BC43: 10123 | BK43: -
K45: Full Runnina Leqqings | AR45: Total | BC45: =BC31+BC33+BC35+BC37+BC39+BC41+BC43+BC43 -> 89011
K48: Remark
K59: * Person in charge (영업담당자) 의 경우, 현지화 대비 영문을 Default 로 등록 (한글사용 지양 필요 - 향후 ESP2 전반적인 수정 필요)
K60: * 기 등록된 오더를 Delete 할 경우, Order Status 에 Delete 로 표현될 뿐, 등록된 내역에 대한 삭제 불용
M63: Order Status
AB64: Order - Reg.
K66: Date | Q66: Initial Reg. date | Z66: ▼ | AC66: YYYY-MM-DD | AL66: ▤ | AN66: ~ | AP66: YYYY-MM-DD | AY66: ▤ | BB66: □ | BD66: Excl. closing File | EH66: Query | EN66: Excel | ET66: Delete
K68: Buyer | Q68: OSHKOSH | Z68: + | AC68: Prod.Depot | AI68: SHWE LIN PAN | AR68: + | AU68: File no. | AZ68: XXXXXXXXXX | BI68: + | BL68: Reg no. | BQ68: TOK-XXXXXXXX | CC68: Person in charge | CM68: (Eng Name) | CY68: Order Status | DF68: Fixed | DM68: ▼
K70: Feedback | R70: Prod. Schedule | AA70: □ | AC70: Fixed | AG70: □ | AI70: not Fixed | AQ70: Update Check | AZ70: □ | BB70: check | BF70: □ | BH70: uncheck
K72: ■ | M72: Reg no. | W72: Sketch | AB72: Person in charge | AK72: Reg Date & Feedback | BG72: Order Info | EH72: Prod. Plan
AK73: Initial | AT73: C | AV73: Last update | BE73: C | BG73: Buyer | BP73: File no. | BY73: PO no. | CH73: Status | CO73: Order Q'ty | CX73: @FOB | DG73: Delivery (1st) | DP73: Delivery (F) | DY73: Factory | EH73: Cutting | EQ73: Sewing
K74: □ | M74: TOK-XXXXXXX1 | AB74: Kevin | AK74: YYYY-MM-DD | AT74: V | AV74: YYYY-MM-DD | BE74: □ | BG74: OSHKOSH | BP74: TY20OK0011 | BY74: 1J056810 | CH74: Fixed | CO74: 89011 | CX74: 3.4 | DG74: 43869 | DP74: 43880 | DY74: SHWE LIN PAN | EH74: 43869 | EQ74: 43880
K75: □ | M75: TOK-XXXXXXX2 | AB75: Kevin | AK75: YYYY-MM-DD | AT75: V | AV75: - | BE75: □ | BG75: OSHKOSH | BP75: TY20OK0012 | BY75: 1J056811 | CH75: Fixed | CO75: 89011 | CX75: 3.4 | DG75: 43869 | DP75: 43880 | DY75: SHWE LIN PAN | EH75: 43869 | EQ75: 43880
K76: □ | M76: TOK-XXXXXXX3 | AB76: Kevin | AK76: YYYY-MM-DD | AT76: □ | AV76: - | BE76: □ | BG76: OSHKOSH | BP76: TY20OK0013 | BY76: 1J056812 | CH76: Not fixed | CO76: 89011 | CX76: 3.4 | DG76: 43869 | DP76: 43880 | DY76: SHWE LIN PAN | EH76: - | EQ76: -
K77: □ | M77: TOK-XXXXXXX4 | AB77: Kevin | AK77: YYYY-MM-DD | AT77: □ | AV77: - | BE77: □ | BG77: OSHKOSH | BP77: - | BY77: 1J056813 | CH77: Delete | CO77: 89011 | CX77: 3.4 | DG77: 43869 | DP77: 43880 | DY77: SHWE LIN PAN | EH77: - | EQ77: -
K79: * File no. 생성전 오더등록 Case 및 File no. 생성후 Overwrite 위해 Reg no. 별도 관리 필요
K80: * Feedback 은 영업에서 등록한 오더에 대한 라인계획 수립 여부 및 오더정보 Update 시 해당 내역 인지하고 조정반영 했는지 여부 회신 관리용
K81: * 기 등록된 오더를 삭제시 (오더캔슬 또는 별도 신규등록 등 원인), Order Status 에 Delete 로 표현될 뿐, 등록된 오더내역 삭제 불가
H85: ※ [PMS 영역]
G89: Production Schedule
E92: Schedule | R92: Schedule - Reg
AQ93: Prod.Depot | AX93: SHWE LIN PAN | BG93: ▼ | BI93: Queyr date | BP93: YYYY-MM-DD | BX93: - | BY93: YYYY-MM-DD | CH93: □ Excl. sketch | DS93: Query | DY93: Excel | EE93: Print | EK93: Save
...

Sheet ESP2.Order Check List
D3: ※ [ESP2] Order Schedule Management
S6: Order -Reg.
G7: Order Status
E9: Buyer | K9: OSHKOSH | T9: + | W9: New Order | AD9: Initial reg. | AK9: YYYY-MM-DD | AS9: Last update | AZ9: YYYY-MM-DD | BW9: Delete | CC9: Save | CI9: Print
E12: Reg no. | K12: TOK-XXXXXXXX | W12: Factory | AB12: SHWE LIN PAN | AK12: + | AN12: Order Status | AW12: Fixed | BF12: ▼ | BI12: Person in charge | BT12: (Eng Name) | CE12: #(Phone Number)
E15: File no. | K15: TY20OK0011 | W15: PO no. | AB15: 193897 | AN15: FOB | AR15: @ PCS | AW15: 3.4
E19: Garment Sketch | R19: + | T19: - | W19: Style no. | AL19: Delivery / Order Q'ty | BI19: Prod. Schedule | BT19: - Request - | CE19: - Prod. Plan -
W22: (Style no.) | AH22: + | AL22: YYYY-MM-DD | AW22: (Order Q'ty) | BE22: + | BI22: Cutting | BT22: YYYY-MM-DD | CE22: YYYY-MM-DD
W25: 1J056810 | AH25: - | AL25: 43869 | AW25: 117 | BE25: - | BI25: Sewing | BT25: YYYY-MM-DD | CE25: YYYY-MM-DD
W27: 2J056810 | AH27: - | AL27: 43870 | AW27: 890 | BE27: -
W29: 3J056810 | AH29: - | AL29: 43871 | AW29: 13362 | BE29: -
AH31: - | AL31: 43875 | AW31: 12416 | BE31: -
AH33: - | AL33: 43876 | AW33: 8592 | BE33: -
AH35: - | AL35: 43877 | AW35: 23382 | BE35: -
AH37: - | AL37: 43880 | AW37: 10123 | BE37: -
E39: Garment Description | AH39: - | AL39: 43880 | AW39: 10123 | BE39: -
E41: Full Runnina Leqqings | AL41: Total | AW41: =AW27+AW29+AW31+AW33+AW35+AW37+AW39+AW39 -> 89011
E44: Remark
E55: * Person in charge (영업담당자) 의 경우, 현지화 대비 영문을 Default 로 등록 (한글사용 지양 필요 - 향후 ESP2 전반적인 수정 필요)
E56: * 기 등록된 오더를 Delete 할 경우, Order Status 에 Delete 로 표현될 뿐, 등록된 내역에 대한 삭제 불용
G60: Order Status
V61: Order - Reg.
E63: Date | K63: Initial Reg. date | T63: ▼ | W63: YYYY-MM-DD | AF63: ▤ | AH63: ~ | AJ63: YYYY-MM-DD | AS63: ▤ | AV63: □ | AX63: Excl. closing File | EB63: Query | EH63: Excel | EN63: Delete
E65: Buyer | K65: OSHKOSH | T65: + | W65: Factory | AC65: SHWE LIN PAN | AL65: + | AO65: File no. | AT65: XXXXXXXXXX | BC65: + | BF65: Reg no. | BK65: TOK-XXXXXXXX | BW65: Person in charge | CG65: (Eng Name) | CS65: Order Status | CZ65: Fixed | DG65: ▼
E67: Feedback | L67: Prod. Schedule | U67: □ | W67: Fixed | AA67: □ | AC67: not Fixed | AK67: Update Check | AT67: □ | AV67: check | AZ67: □ | BB67: uncheck
E69: ■ | G69: Reg no. | Q69: Sketch | V69: Person in charge | AE69: Reg Date & Feedback | BA69: Order Info | EB69: Prod. Plan
AE70: Initial | AN70: F | AP70: Last update | AY70: C | BA70: Buyer | BJ70: File no. | BS70: PO no. | CB70: Status | CI70: Order Q'ty | CR70: @FOB | DA70: Delivery (1st) | DJ70: Delivery (F) | DS70: Factory | EB70: Cutting | EK70: Sewing
E71: □ | G71: TOK-XXXXXXX1 | V71: Kevin | AE71: YYYY-MM-DD | AN71: V | AP71: YYYY-MM-DD | AY71: □ | BA71: OSHKOSH | BJ71: TY20OK0011 | BS71: 1J056810 | CB71: Fixed | CI71: 89011 | CR71: 3.4 | DA71: 43869 | DJ71: 43880 | DS71: SHWE LIN PAN | EB71: 43869 | EK71: 43880
E72: □ | G72: TOK-XXXXXXX2 | V72: Kevin | AE72: YYYY-MM-DD | AN72: V | AP72: - | AY72: □ | BA72: OSHKOSH | BJ72: TY20OK0012 | BS72: 1J056811 | CB72: Fixed | CI72: 89011 | CR72: 3.4 | DA72: 43869 | DJ72: 43880 | DS72: SHWE LIN PAN | EB72: 43869 | EK72: 43880
E73: □ | G73: TOK-XXXXXXX3 | V73: Kevin | AE73: YYYY-MM-DD | AN73: □ | AP73: - | AY73: □ | BA73: OSHKOSH | BJ73: TY20OK0013 | BS73: 1J056812 | CB73: Not fixed | CI73: 89011 | CR73: 3.4 | DA73: 43869 | DJ73: 43880 | DS73: SHWE LIN PAN | EB73: - | EK73: -
E74: □ | G74: TOK-XXXXXXX4 | V74: Kevin | AE74: YYYY-MM-DD | AN74: □ | AP74: - | AY74: □ | BA74: OSHKOSH | BJ74: - | BS74: 1J056813 | CB74: Delete | CI74: 89011 | CR74: 3.4 | DA74: 43869 | DJ74: 43880 | DS74: SHWE LIN PAN | EB74: - | EK74: -
E77: * File no. 생성전 오더등록 Case 및 File no. 생성후 Overwrite 위해 Reg no. 별도 관리 필요
E78: * Feedback 은 영업에서 등록한 오더에 대한 라인계획 수립 여부 및 오더정보 Update 시 해당 내역 인지하고 조정반영 했는지 여부 회신 관리용
E79: * 기 등록된 오더를 삭제시 (오더캔슬 또는 별도 신규등록 등 원인), Order Status 에 Delete 로 표현될 뿐, 등록된 오더내역 삭제 불용

Sheet 3-2.Monitoring
F2: 3-2-2. Production Status by line (Monitoring)
H5: Hourly Production Status (by Q'ty) | T5: Hourly Production Status (by Amt) | AD5: Chart
W6: ↑ Amt (생산액) 기준 화면은 하단에 공장계 (Prod.Depot) 가 있어야 함
H7: Prod. Date | O7: YYYY-MM-DD | U7: ▤ | AM7: ↓ 생산일수
H9: Prod. Depot | O9: MY1 - Sewing Line | U9: + | AR9: ↓ 목표대비 Color 환경설정 가능해야 함
O13: Today | AA13: Hourly | AM13: Prod. | AR13: Hourly Sewing performance
H14: Factory
O15: Target | S15: Actual | W15: Prog. % | AA15: H.Target | AE15: H.AVG | AI15: Achieve.% | AM15: Dur. | AR15: 1H | AT15: 2H | AV15: 3H | AX15: 4H | AZ15: 5H | BB15: 6H | BD15: 7H | BF15: 8H | BH15: 9H | BJ15: 10H | BL15: 11H | BN15: 12H
H17: Line 01 | O17: 100 | S17: =SUM(AR17:BN17) -> 76 | W17: =S17/O17 -> 0.76 | AA17: =O17/8 -> 12.5 | AE17: =IF(COUNTA(AR17,AT17,AV17,AX17,AZ17,BB17,BD17,BF17,BH17,BJ17,BL17,BN17)=0,0,S17/COUNTA(AR17,AT17,AV17,AX17,AZ17,BB17,BD17,BF17,BH17,BJ17,BL17,BN17)) -> 12.666667 | AI17: =AE17/AA17 -> 1.0133333 | AM17: 10 | AR17: 10 | AT17: 12 | AV17: 13 | AX17: 13 | AZ17: 14 | BB17: 14
H19: Line 02 | O19: 150 | S19: =SUM(AR19:BN19) -> 101 | W19: =S19/O19 -> 0.67333333 | AA19: =O19/8 -> 18.75 | AE19: =IF(COUNTA(AR19,AT19,AV19,AX19,AZ19,BB19,BD19,BF19,BH19,BJ19,BL19,BN19)=0,0,S19/COUNTA(AR19,AT19,AV19,AX19,AZ19,BB19,BD19,BF19,BH19,BJ19,BL19,BN19)) -> 16.833333 | AI19: =AE19/AA19 -> 0.89777778 | AM19: 3 | AR19: 8 | AT19: 15 | AV19: 16 | AX19: 18 | AZ19: 22 | BB19: 22
H21: Line 03 | O21: 200 | S21: =SUM(AR21:BN21) -> 123 | W21: =S21/O21 -> 0.615 | AA21: =O21/8 -> 25 | AE21: =IF(COUNTA(AR21,AT21,AV21,AX21,AZ21,BB21,BD21,BF21,BH21,BJ21,BL21,BN21)=0,0,S21/COUNTA(AR21,AT21,AV21,AX21,AZ21,BB21,BD21,BF21,BH21,BJ21,BL21,BN21)) -> 20.5 | AI21: =AE21/AA21 -> 0.82 | AM21: 1 | AR21: 15 | AT21: 21 | AV21: 20 | AX21: 23 | AZ21: 22 | BB21: 22
H23: Line 04 | O23: 100 | S23: =SUM(AR23:BN23) -> 67 | W23: =S23/O23 -> 0.67 | AA23: =O23/8 -> 12.5 | AE23: =IF(COUNTA(AR23,AT23,AV23,AX23,AZ23,BB23,BD23,BF23,BH23,BJ23,BL23,BN23)=0,0,S23/COUNTA(AR23,AT23,AV23,AX23,AZ23,BB23,BD23,BF23,BH23,BJ23,BL23,BN23)) -> 11.166667 | AI23: =AE23/AA23 -> 0.89333333 | AM23: 5 | AR23: 14 | AT23: 10 | AV23: 11 | AX23: 8 | AZ23: 12 | BB23: 12
H25: Line 05 | O25: 230 | S25: =SUM(AR25:BN25) -> 139 | W25: =S25/O25 -> 0.60434783 | AA25: =O25/8 -> 28.75 | AE25: =IF(COUNTA(AR25,AT25,AV25,AX25,AZ25,BB25,BD25,BF25,BH25,BJ25,BL25,BN25)=0,0,S25/COUNTA(AR25,AT25,AV25,AX25,AZ25,BB25,BD25,BF25,BH25,BJ25,BL25,BN25)) -> 23.166667 | AI25: =AE25/AA25 -> 0.8057971 | AM25: 5 | AR25: 20 | AT25: 18 | AV25: 22 | AX25: 25 | AZ25: 27 | BB25: 27
H27: Line 06 | O27: 150 | S27: =SUM(AR27:BN27) -> 88 | W27: =S27/O27 -> 0.58666667 | AA27: =O27/8 -> 18.75 | AE27: =IF(COUNTA(AR27,AT27,AV27,AX27,AZ27,BB27,BD27,BF27,BH27,BJ27,BL27,BN27)=0,0,S27/COUNTA(AR27,AT27,AV27,AX27,AZ27,BB27,BD27,BF27,BH27,BJ27,BL27,BN27)) -> 14.666667 | AI27: =AE27/AA27 -> 0.78222222 | AM27: 5 | AR27: 5 | AT27: 16 | AV27: 15 | AX27: 12 | AZ27: 20 | BB27: 20
H29: Line 07 | O29: 200 | S29: =SUM(AR29:BN29) -> 68 | W29: =S29/O29 -> 0.34 | AA29: =O29/8 -> 25 | AE29: =IF(COUNTA(AR29,AT29,AV29,AX29,AZ29,BB29,BD29,BF29,BH29,BJ29,BL29,BN29)=0,0,S29/COUNTA(AR29,AT29,AV29,AX29,AZ29,BB29,BD29,BF29,BH29,BJ29,BL29,BN29)) -> 11.333333 | AI29: =AE29/AA29 -> 0.45333333 | AM29: 3 | AR29: 10 | AT29: 11 | AV29: 12 | AX29: 9 | AZ29: 13 | BB29: 13
H31: Line 08 | O31: 100 | S31: =SUM(AR31:BN31) -> 89 | W31: =S31/O31 -> 0.89 | AA31: =O31/8 -> 12.5 | AE31: =IF(COUNTA(AR31,AT31,AV31,AX31,AZ31,BB31,BD31,BF31,BH31,BJ31,BL31,BN31)=0,0,S31/COUNTA(AR31,AT31,AV31,AX31,AZ31,BB31,BD31,BF31,BH31,BJ31,BL31,BN31)) -> 14.833333 | AI31: =AE31/AA31 -> 1.1866667 | AM31: 3 | AR31: 15 | AT31: 13 | AV31: 12 | AX31: 15 | AZ31: 18 | BB31: 16
H33: Line 09 | O33: 50 | S33: =SUM(AR33:BN33) -> 51 | W33: =S33/O33 -> 1.02 | AA33: =O33/8 -> 6.25 | AE33: =IF(COUNTA(AR33,AT33,AV33,AX33,AZ33,BB33,BD33,BF33,BH33,BJ33,BL33,BN33)=0,0,S33/COUNTA(AR33,AT33,AV33,AX33,AZ33,BB33,BD33,BF33,BH33,BJ33,BL33,BN33)) -> 8.5 | AI33: =AE33/AA33 -> 1.36 | AM33: 3 | AR33: 10 | AT33: 10 | AV33: 9 | AX33: 6 | AZ33: 8 | BB33: 8
H35: Line 10 | O35: 50 | S35: =SUM(AR35:BN35) -> 56 | W35: =S35/O35 -> 1.12 | AA35: =O35/8 -> 6.25 | AE35: =IF(COUNTA(AR35,AT35,AV35,AX35,AZ35,BB35,BD35,BF35,BH35,BJ35,BL35,BN35)=0,0,S35/COUNTA(AR35,AT35,AV35,AX35,AZ35,BB35,BD35,BF35,BH35,BJ35,BL35,BN35)) -> 9.3333333 | AI35: =AE35/AA35 -> 1.4933333 | AM35: 1 | AR35: 10 | AT35: 10 | AV35: 11 | AX35: 8 | AZ35: 8 | BB35: 9

Sheet 3-2-1
AU5: Chart
K6: Hourly Production Status (by Qty) | AC6: Hourly Production Status (by Amt)
K8: Query date | R8: YYYY-MM-DD | AA8: ▤ | AC8: ~ | AE8: YYYY-MM-DD | AN8: ▤
K11: Prod.Depot | R11: SHWE LIN PAN | AA11: ▼ | AD11: Prod. Line | AK11: 1111 | AQ11: MY1.Line_01 | AZ11: ▼
O14: ◎ by End-line Sewing record ○ by Net Production amount
K17: Prod. (Amt) | AX17: Accumulate
AY20: T | BA20: C | BC20: A | BE20: D
R40: 1 | T40: 2 | V40: 3 | X40: 4 | Z40: 5 | AB40: 6 | AD40: 7 | AF40: 8 | AH40: 9 | AJ40: 10
J42: * Accumulate : T (Target), C (End-line counting), A (Net Prod. - 불량제외), D (Defect)

Sheet 4.EXIM
E3: Ⅳ. Garment W/H
F5: ※ System Menu 구성
H7: ◆ Garment W/H | O7: ◆ Garment W/H IN-OUT | Y7: □ | Z7: G. W/H PKG - Reg. | AM7: : 완성품 Pakage 등록
O9: ◆ EXPORT | Y9: □ | Z9: Ex-factory - Reg. | AM9: : 완성품 출하(Ex-factory) 등록
F13: 4-1. EXPORT
G15: 4-1-1. Ex-factory - Reg.
I18: Ex-factory - Reg. | P18: Status
I20: Reg Date | M20: YYYY-MM-DD | Q20: ▤ | R20: □ | S20: Date Modify | AE20: Ex-factory Reg. no | AJ20: XXXXXXXXXX | BJ20: SAVE | BM20: Delete
I22: - Ex-factory Header Info.
I24: ■ | J24: Invoice no. | O24: Ex-fac. Date | T24: On Board Date | Y24: Final Inspection | AD24: Transport | AI24: Destination | AN24: Carrier | AS24: B/L no. | AX24: B/L Date | BC24: ETA | BH24: Order Q'ty | BL24: Ex-fac. Q'ty
I25: □ | J25: XXXXXXXXXXXXX | O25: YYYY-MM-DD | S25: + | T25: YYYY-MM-DD | X25: + | Y25: YYYY-MM-DD | AC25: + | AD25: VESSEL | AH25: ▼ | AI25: US | AM25: ▼ | AN25: XXXXXXX | AR25: + | AS25: XXXXXXXXXXXXX | AX25: YYYY-MM-DD | BB25: + | BC25: YYYY-MM-DD | BG25: + | BH25: 600 | BL25: 601
I28: - Ex-factory File Info. | P28: (+) ADD | S28: (+) COPY & ADD | W28: (-) DEL
I30: ■ | J30: Order | AJ30: Ex-factory | BG30: Remark
J31: File no. | O31: Style no. | R31: SEQ | T31: PO no. | W31: Style Color | AC31: Size | AF31: Order Q'ty | AJ31: Factory | AP31: Ex-fac. Q'ty | AT31: Ex-fac. KGS | AX31: Ex-fac. Amt | BB31: Export Permit no. | BO31: ▤
I32: □ | J32: TN18TK7043 | N32: + | O32: 241657 | R32: 11 | T32: QC81T | W32: BCVC13(PL106) | AC32: 18M | AF32: 1200 | AJ32: MASAYA1 | AO32: ▼ | AP32: 600 | AT32: 100 | AX32: =AP32*3 -> 1800 | BB32: XXXXXXXXXXXXX
I33: □ | J33: TN18TK7043 | N33: + | O33: 241657 | R33: 11 | T33: QC81T | W33: BCVC13(PL106) | AC33: 4T | AF33: 1200 | AJ33: MASAYA2 | AO33: ▼ | AP33: 599 | AT33: 100 | AX33: =AP33*3 -> 1797 | BB33: XXXXXXXXXXXXX
I34: □ | J34: TN18TK7043 | N34: + | O34: 241657 | R34: A1 | T34: QC81 | W34: BCVC13(PL106) | AC34: S | AF34: 600 | AJ34: TEXNICA | AO34: ▼ | AP34: 590 | AT34: 95 | AX34: =AP34*3 -> 1770 | BB34: XXXXXXXXXXXXX
AC37: Total | AF37: =AF34+AF33+AF32 -> 3000 | AP37: =AP34+AP33+AP32 -> 1789 | AT37: =AT34+AT33+AT32 -> 295 | AX37: =AX34+AX33+AX32 -> 5367
I40: ※ Summary (Shortage Info.) | P40: *** 해당 Summary 자료 필요한지 여부 점검
I42: ■ | J42: Order | AF42: Q'ty
J43: File no. | O43: Style no. | R43: SEQ | T43: PO no. | W43: Style Color | AC43: Size | AF43: Order Q'ty | AJ43: Ex-fac. Q'ty | AN43: Shortage | AR43: ▤
I44: □ | J44: TN18TK7043 | O44: Style no. | R44: 11 | T44: QC81T | W44: BCVC13(PL106) | AC44: 18M | AF44: 1200 | AJ44: =AP32+AP33 -> 1199 | AN44: =AJ44-AF44 -> -1
I45: □ | J45: TN18TK7043 | O45: Style no. | R45: A1 | T45: QC81 | W45: BCVC13(PL106) | AC45: 4T | AF45: 600 | AJ45: 590 | AN45: =AJ45-AF45 -> -10
AC48: Total | AF48: =AF44+AF45 -> 1800 | AJ48: =AJ44+AJ45 -> 1789 | AN48: =AJ48-AF48 -> -11
G53: 4-1-2. Ex-factory Status
H55: * 기간조회 기준 : Reg Date, Ex-factory Date, On Board Date
H56: * 하기 Status 외, 현황 Report 추가요청 가능성 高
I59: Ex-factory - Reg. | P59: Status
I61: Reg Date | N61: ▼ | P61: YYYY-MM-DD | T61: ▤ | U61: ~ | V61: YYYY-MM-DD | Z61: ▤ | AB61: Factory | AE61: MASAYA1 | AJ61: ▼ | BU61: Query | BX61: Excel
I63: Buyer | L63: XXXXXXXXXX | P63: + | R63: File no | U63: XXXXXXXXXX | Y63: + | Z63: Style no | AC63: XXXXXXXXXX | AG63: + | AI63: PO no | AL63: XXXXXXXXXX | AQ63: Ex-factory Reg. no | AV63: XXXXXXXXXX | BA63: Invoice no | BE63: XXXXXXXXXX
I65: ■ | J65: Reg. Date | N65: Ex-Factory Reg. no | S65: Invoice no | X65: Buyer | AC65: File no. | AG65: Style no. | AJ65: SEQ | AL65: PO no. | AO65: Style Color | AU65: Size | AX65: Factory | BC65: Final Inspection | BG65: Ex-fac. Date | BK65: Ex-fac. Q'ty | BO65: Ex-fac. Amt | BS65: On Board Date | BW65: Closing Date
I66: □ | J66: YYYY-MM-DD | N66: XXXXXXXXXX | S66: XXXXXXXXXX | X66: Buyer | AC66: TN18TK7043 | AG66: Style no. | AJ66: 11 | AL66: QC81T | AO66: BCVC13(PL106) | AU66: 18M | AX66: MASAYA1 | BC66: YYYY-MM-DD | BG66: YYYY-MM-DD | BK66: 601 | BO66: 1803 | BS66: YYYY-MM-DD
I67: □ | J67: YYYY-MM-DD | N67: XXXXXXXXXX | S67: XXXXXXXXXX | X67: Buyer | AC67: TN18TK7043 | AG67: Style no. | AJ67: A1 | AL67: QC81T | AO67: BCVC13(PL106) | AU67: 4T | AX67: MASAYA1 | BC67: YYYY-MM-DD | BG67: YYYY-MM-DD | BK67: 601 | BO67: 1803 | BS67: YYYY-MM-DD
I68: □ | J68: YYYY-MM-DD | N68: XXXXXXXXXX | S68: XXXXXXXXXX | X68: Buyer | AC68: TN18TK7043 | AG68: Style no. | AJ68: A1 | AL68: QC81T | AO68: BCVC13(PL106) | AU68: 4T | AX68: MASAYA1 | BC68: YYYY-MM-DD | BG68: YYYY-MM-DD | BK68: 601 | BO68: 1803 | BS68: YYYY-MM-DD
BG71: Total | BK71: =BK68+BK67+BK66 -> 1803 | BO71: =BO68+BO67+BO66 -> 5409
F77: 4-2. IMPORT
G79: 4-2-1. Import Material - Reg.
I81: : Local 수입서류 관리목적 - 생산관리시스템과 연동되는 Data 없이, 별도 Reg, Status 관리중 (각 법인의 Needs 에 따라 옵션으로 개발 진행)
G106: 4-2-2. Import Material Status
I108: : 5-1-1 내용 참조

Sheet 5.Garment Stock
E3: V. Garment Stock W/H
F5: 5-1. Garment Stock IN - Reg. | AD5: * 입고증 출력 버튼 없음
H8: Garment Stock IN - Reg. | O8: Status
H10: W/H IN Date | L10: YYYY-MM-DD | P10: ▤ | Q10: □ | R10: Date Modify | U10: Depot | X10: Garment Stock W/H | AD10: + | AK10: SAVE | AN10: Delete
H12: Source Depot | L12: MY1 - Sewing Line | R12: +
H14: W/H Location | L14: (L.Type) | O14: ▼ | P14: P01 | S14: ▼ | T14: L01-C01 | W14: ▼
H16: File/Style no | L16: XXXXXXXXXX | P16: XXXXXXXXXX | T16: + | U16: (+) ADD | X16: (+) COPY & ADD | AB16: (-) DEL | AH16: IN Reg. no | AL16: XXXXXXXXXX
H18: ■ | I18: Depot | N18: W/H Location | W18: Order | AJ18: SIZE | AM18: IN Q'ty (PCS)
N19: Type | Q19: Class 1 | T19: Class 2 | W19: File no. | AA19: Style no. | AD19: Style Color | AP19: ▤
H20: □ | I20: Garment Stock W/H | N20: (L.Type) | Q20: P01 | T20: L01-C01 | W20: TN18TK7043 | AA20: 241657 | AD20: BCVC13(PL106) | AI20: ▼ | AJ20: 18M | AL20: ▼ | AM20: 13
H21: □ | I21: Garment Stock W/H | N21: (L.Type) | Q21: P01 | T21: L01-C01 | W21: TN18TK7043 | AA21: 241657 | AD21: BCVC13(PL106) | AI21: ▼ | AJ21: 4T | AL21: ▼ | AM21: 13
H22: □ | I22: Garment Stock W/H | N22: (L.Type) | Q22: P01 | T22: L01-C01 | W22: TN18TK7043 | AA22: 241657 | AD22: BCVC13(PL106) | AI22: ▼ | AJ22: S | AL22: ▼ | AM22: 19
AJ25: PCS Q'ty | AM25: =AM22+AM21+AM20 -> 45
F30: 5-2. Garment Stock OUT - Reg.
H33: Garment Stock OUT - Reg. | O33: Status
H35: W/H OUT Date | L35: YYYY-MM-DD | P35: ▤ | Q35: □ | R35: Date Modify | U35: Depot | X35: Garment Stock W/H | AD35: + | AG35: Query | AJ35: SAVE | AM35: Delete
H37: [ Stock Query ]
H39: W/H Location | L39: (L.Type) | O39: ▼ | P39: P01 | S39: ▼ | T39: L01-C01 | W39: ▼
H41: File/Style no | L41: XXXXXXXXXX | P41: XXXXXXXXXX | T41: + | U41: (+) ADD | X41: (+) COPY & ADD | AB41: (-) DEL
H43: ■ | I43: Depot | O43: W/H Location | X43: Order | AJ43: SIZE | AL43: Q'ty
