Workbook

Sheet 순서
B2: 1. 공급미수관리
C3: - 백화점 EDI 발주의뢰등록(매입/반품)
B5: 2. 월 유통망별 매출집계
C6: - 직영점 : 현금 및 카드사별 매출 관리
C7: - 직영점 외 : 임대(을) -매출 관리
C8: 특정매입 - 매출 세금계산서 정산(판매/공급분 구분)
C9: - 온라인 : 외부마켓 매출관리 및 정산
B11: 3. 미수 및 입금 관리
C12: - 판매/공급 미수관리(F-ONE 잔액 = 계정잔액)
C13: - 직영점 외 매장 입금 확인 및 관리
B15: 4. 중간관리자 수수료 지급
C16: - 중간관리자 수수료 세금계산서 발행 (역발행)
C17: - 중간관리자 공제내역 세금계산서 발행 (정발행)
D18: - 개별공제 내역 회계팀 전달
C20: **요청사항 : 슬라이딩 수수료 적용 화면 요청

Sheet 직영점정산
A2: 1. 월 유통망별 매출집계
A3: - 매니저 판매일보, FONE매출, 카드사별 매출 확인
B5: 1) 매니저 판매일보
S36: 3) FONE 매출
B37: 2) 카드사 매출
A72: 2. 미수 관리 및 입금관리
Z95: **매장 입금내역현황

Sheet 카드사별매출
A1: * 대상기간 : 2022년 08월 01일 ~ 2022년 08월 31일
A2: * 지점명 : 에디션ANDZ아산퍼스트빌(본사)
A4: 사업자번호 | B4: 상호 | C4: 거래일자 | D4: 거래시간 | E4: 카드번호 | F4: 승인번호 | G4: 매입사 | H4: 금액 | I4: 처리현황 | J4: 거래유형 | K4: 반송사유 | L4: 입금예정 | M4: 단말기종류 | N4: 가맹점번호 | O4: 수수료 | P4: 입금예정액 | Q4: 단말기 | R4: 점코드 | S4: 발급사 | T4: 거래결과 | U4: 대리점연락처 | V4: 단말기구분 | W4: 세금 | X4: 비과세금액 | Y4: 밴CODE | Z4: 그룹코드 | AA4: 대리점 | AB4: 취소여부
A5: 108-85-35722 | B5: 신성통상에디션ANDZ퍼스트빌 | C5: 2022-08-01 | D5: 11:07:39 | E5: 5107-37**-****-7340 | F5: 46315411 | G5: 신한 | H5: 64000 | I5: 입금완료 | J5: 승인 | L5: 2022-08-04 | M5: CAT | N5: 0112786827 | O5: 960 | P5: 63040 | Q5: 11908757 | S5: 신한 | T5: (0000) 정상완료 | U5: 18991271 | V5: CAT(유선) | W5: 5818 | X5: 0 | Y5: FDIK | Z5: 7500 | AA5: (주)제일좋은솔루션
A6: 108-85-35722 | B6: 신성통상에디션ANDZ퍼스트빌 | C6: 2022-08-01 | D6: 14:54:10 | E6: 4273-52**-****-3564 | F6: 78480180 | G6: 비씨 | H6: 170000 | I6: 입금완료 | J6: 승인 | K6: 정상 | L6: 2022-08-04 | M6: CAT | N6: 712781159 | O6: 2295 | P6: 167705 | Q6: 11908757 | S6: 비씨 | T6: (0000) 정상완료 | U6: 18991271 | V6: CAT(유선) | W6: 15454 | X6: 0 | Y6: FDIK | Z6: 7500 | AA6: (주)제일좋은솔루션
A7: 108-85-35722 | B7: 신성통상에디션ANDZ퍼스트빌 | C7: 2022-08-01 | D7: 15:03:46 | E7: 9409-15**-****-4623 | F7: 64103155 | G7: 롯데 | H7: 69000 | I7: 입금완료 | J7: 승인 | K7: 정상 | L7: 2022-08-04 | M7: CAT | N7: 9958307570 | O7: 1587 | P7: 67413 | Q7: 11908757 | S7: 롯데 | T7: (0000) 정상완료 | U7: 18991271 | V7: CAT(유선) | W7: 6272 | X7: 0 | Y7: FDIK | Z7: 7500 | AA7: (주)제일좋은솔루션
A8: 108-85-35722 | B8: 신성통상에디션ANDZ퍼스트빌 | C8: 2022-08-01 | D8: 15:21:37 | E8: 4033-02**-****-7317 | F8: 00327228 | G8: 현대 | H8: 88000 | I8: 입금완료 | J8: 승인 | K8: 정상 | L8: 2022-08-04 | M8: CAT | N8: 310963063 | O8: 2024 | P8: 85976 | Q8: 11908757 | S8: 현대 | T8: (0000) 정상완료 | U8: 18991271 | V8: CAT(유선) | W8: 8000 | X8: 0 | Y8: FDIK | Z8: 7500 | AA8: (주)제일좋은솔루션 | AD8: 행 레이블 | AE8: 합계 : 금액 | AF8: 합계 : 수수료 | AG8: 합계 : 입금예정액
A9: 108-85-35722 | B9: 신성통상에디션ANDZ퍼스트빌 | C9: 2022-08-01 | D9: 15:31:22 | E9: 4579-72**-****-7079 | F9: 30034431 | G9: KB국민 | H9: 29000 | I9: 입금완료 | J9: 승인 | K9: 정상 | L9: 2022-08-04 | M9: CAT | N9: 00092318201 | O9: 667 | P9: 28333 | Q9: 11908757 | S9: KB국민 | T9: (0000) 정상완료 | U9: 18991271 | V9: CAT(유선) | W9: 2636 | X9: 0 | Y9: FDIK | Z9: 7500 | AA9: (주)제일좋은솔루션 | AD9: KB국민 | AE9: 2087000 | AF9: 38556 | AG9: 2048444
A10: 108-85-35722 | B10: 신성통상에디션ANDZ퍼스트빌 | C10: 2022-08-01 | D10: 15:49:23 | E10: 9410-09**-****-1039 | F10: 05223852 | G10: 삼성 | H10: 188000 | I10: 입금완료 | J10: 승인 | K10: 정상 | L10: 2022-08-04 | M10: CAT | N10: 173060897 | O10: 4324 | P10: 183676 | Q10: 11908757 | S10: 삼성 | T10: (0000) 정상완료 | U10: 18991271 | V10: CAT(유선) | W10: 17090 | X10: 0 | Y10: FDIK | Z10: 7500 | AA10: (주)제일좋은솔루션 | AD10: 농협 | AE10: 3486500 | AF10: 64515 | AG10: 3421985
A11: 108-85-35722 | B11: 신성통상에디션ANDZ퍼스트빌 | C11: 2022-08-01 | D11: 17:06:50 | E11: 4574-92**-****-9906 | F11: 00468718 | G11: 현대 | H11: 196000 | I11: 입금완료 | J11: 승인 | K11: 정상 | L11: 2022-08-04 | M11: CAT | N11: 310963063 | O11: 4508 | P11: 191492 | Q11: 11908757 | S11: 현대 | T11: (0000) 정상완료 | U11: 18991271 | V11: CAT(유선) | W11: 17818 | X11: 0 | Y11: FDIK | Z11: 7500 | AA11: (주)제일좋은솔루션 | AD11: 롯데 | AE11: 521000 | AF11: 11983 | AG11: 509017
A12: 108-85-35722 | B12: 신성통상에디션ANDZ퍼스트빌 | C12: 2022-08-01 | D12: 17:15:45 | E12: 6210-12**-****-2412 | F12: 70442181 | G12: 비씨 | H12: 118000 | I12: 입금완료 | J12: 승인 | K12: 정상 | L12: 2022-08-04 | M12: CAT | N12: 712781159 | O12: 1711 | P12: 116289 | Q12: 11908757 | S12: 비씨 | T12: (0000) 정상완료 | U12: 18991271 | V12: CAT(유선) | W12: 10727 | X12: 0 | Y12: FDIK | Z12: 7500 | AA12: (주)제일좋은솔루션 | AD12: 비씨 | AE12: 3224000 | AF12: 53790 | AG12: 3170210
A13: 108-85-35722 | B13: 신성통상에디션ANDZ퍼스트빌 | C13: 2022-08-01 | D13: 18:21:03 | E13: 5188-31**-****-4474 | F13: 53276245 | G13: 삼성 | H13: 39000 | I13: 입금완료 | J13: 승인 | K13: 정상 | L13: 2022-08-04 | M13: CAT | N13: 173060897 | O13: 897 | P13: 38103 | Q13: 11908757 | S13: 삼성 | T13: (0000) 정상완료 | U13: 18991271 | V13: CAT(유선) | W13: 3545 | X13: 0 | Y13: FDIK | Z13: 7500 | AA13: (주)제일좋은솔루션 | AD13: 삼성 | AE13: 1247000 | AF13: 28681 | AG13: 1218319
A14: 108-85-35722 | B14: 신성통상에디션ANDZ퍼스트빌 | C14: 2022-08-01 | D14: 20:01:28 | E14: 4518-42**-****-7405 | F14: 04759762 | G14: 신한 | H14: 39000 | I14: 입금완료 | J14: 승인 | L14: 2022-08-04 | M14: CAT | N14: 0112786827 | O14: 897 | P14: 38103 | Q14: 11908757 | S14: 신한 | T14: (0000) 정상완료 | U14: 18991271 | V14: CAT(유선) | W14: 3545 | X14: 0 | Y14: FDIK | Z14: 7500 | AA14: (주)제일좋은솔루션 | AD14: 신한 | AE14: 1877500 | AF14: 38534 | AG14: 1838966
A15: 108-85-35722 | B15: 신성통상에디션ANDZ퍼스트빌 | C15: 2022-08-02 | D15: 13:21:38 | E15: 5387-20**-****-3812 | F15: 78162299 | G15: 비씨 | H15: 39000 | I15: 입금완료 | J15: 승인 | K15: 정상 | L15: 2022-08-05 | M15: CAT | N15: 712781159 | O15: 897 | P15: 38103 | Q15: 11908757 | S15: 비씨 | T15: (0000) 정상완료 | U15: 18991271 | V15: CAT(유선) | W15: 3545 | X15: 0 | Y15: FDIK | Z15: 7500 | AA15: (주)제일좋은솔루션 | AD15: 외환 | AE15: 928000 | AF15: 20671 | AG15: 907329
A16: 108-85-35722 | B16: 신성통상에디션ANDZ퍼스트빌 | C16: 2022-08-02 | D16: 13:48:03 | E16: 3569-08**-****-2907 | F16: 12246124 | G16: 신한 | H16: 39000 | I16: 입금완료 | J16: 승인 | L16: 2022-08-05 | M16: CAT | N16: 0112786827 | O16: 897 | P16: 38103 | Q16: 11908757 | S16: 신한 | T16: (0000) 정상완료 | U16: 18991271 | V16: CAT(유선) | W16: 3545 | X16: 0 | Y16: FDIK | Z16: 7500 | AA16: (주)제일좋은솔루션 | AD16: 현대 | AE16: 1534400 | AF16: 35291 | AG16: 1499109
A17: 108-85-35722 | B17: 신성통상에디션ANDZ퍼스트빌 | C17: 2022-08-02 | D17: 14:39:08 | E17: 9430-16**-****-1026 | F17: 66457788 | G17: 농협 | H17: 49000 | I17: 입금완료 | J17: 승인 | L17: 2022-08-05 | M17: CAT | N17: 148832581 | O17: 1127 | P17: 47873 | Q17: 11908757 | S17: 농협 | T17: (0000) 정상완료 | U17: 18991271 | V17: CAT(유선) | W17: 4454 | X17: 0 | Y17: FDIK | Z17: 7500 | AA17: (주)제일좋은솔루션 | AD17: 총합계 | AE17: 14905400 | AF17: 292021 | AG17: 14613379
A18: 108-85-35722 | B18: 신성통상에디션ANDZ퍼스트빌 | C18: 2022-08-02 | D18: 14:43:17 | E18: 5417-07**-****-5906 | F18: 28000151 | G18: 외환 | H18: 327000 | I18: 입금완료 | J18: 승인 | K18: 정상 | L18: 2022-08-05 | M18: CAT | N18: 00994444693 | O18: 7521 | P18: 319479 | Q18: 11908757 | S18: 하나 | T18: (0000) 정상완료 | U18: 18991271 | V18: CAT(유선) | W18: 29727 | X18: 0 | Y18: FDIK | Z18: 7500 | AA18: (주)제일좋은솔루션
A19: 108-85-35722 | B19: 신성통상에디션ANDZ퍼스트빌 | C19: 2022-08-02 | D19: 15:30:25 | E19: 4364-20**-****-9522 | F19: 13562015 | G19: 신한 | H19: 100000 | I19: 입금완료 | J19: 승인 | L19: 2022-08-05 | M19: CAT | N19: 0112786827 | O19: 1500 | P19: 98500 | Q19: 11908757 | S19: 신한 | T19: (0000) 정상완료 | U19: 18991271 | V19: CAT(유선) | W19: 9090 | X19: 0 | Y19: FDIK | Z19: 7500 | AA19: (주)제일좋은솔루션
A20: 108-85-35722 | B20: 신성통상에디션ANDZ퍼스트빌 | C20: 2022-08-02 | D20: 18:32:32 | E20: 4330-28**-****-7005 | F20: 00507644 | G20: 현대 | H20: 69000 | I20: 입금완료 | J20: 승인 | K20: 정상 | L20: 2022-08-05 | M20: CAT | N20: 310963063 | O20: 1587 | P20: 67413 | Q20: 11908757 | S20: 현대 | T20: (0000) 정상완료 | U20: 18991271 | V20: CAT(유선) | W20: 6272 | X20: 0 | Y20: FDIK | Z20: 7500 | AA20: (주)제일좋은솔루션
A21: 108-85-35722 | B21: 신성통상에디션ANDZ퍼스트빌 | C21: 2022-08-03 | D21: 12:05:22 | E21: 4658-87**-****-0545 | F21: 22781068 | G21: 신한 | H21: 209000 | I21: 입금완료 | J21: 승인 | L21: 2022-08-08 | M21: CAT | N21: 0112786827 | O21: 4807 | P21: 204193 | Q21: 11908757 | S21: 신한 | T21: (0000) 정상완료 | U21: 18991271 | V21: CAT(유선) | W21: 19000 | X21: 0 | Y21: FDIK | Z21: 7500 | AA21: (주)제일좋은솔루션
A22: 108-85-35722 | B22: 신성통상에디션ANDZ퍼스트빌 | C22: 2022-08-03 | D22: 12:15:55 | E22: 4658-87**-****-0545 | F22: 22958245 | G22: 신한 | H22: 59000 | I22: 입금완료 | J22: 승인 | L22: 2022-08-08 | M22: CAT | N22: 0112786827 | O22: 1357 | P22: 57643 | Q22: 11908757 | S22: 신한 | T22: (0000) 정상완료 | U22: 18991271 | V22: CAT(유선) | W22: 5363 | X22: 0 | Y22: FDIK | Z22: 7500 | AA22: (주)제일좋은솔루션 | AD22: KB국민 | AE22: 2087000 | AF22: 38556 | AG22: 2048444 | AH22: =+AE22-AF22-AG22 -> 0
A23: 108-85-35722 | B23: 신성통상에디션ANDZ퍼스트빌 | C23: 2022-08-03 | D23: 13:08:18 | E23: 5461-12**-****-2672 | F23: 74654570 | G23: 농협 | H23: 98000 | I23: 입금완료 | J23: 승인 | L23: 2022-08-08 | M23: CAT | N23: 148832581 | O23: 1421 | P23: 96579 | Q23: 11908757 | S23: 농협 | T23: (0000) 정상완료 | U23: 18991271 | V23: CAT(유선) | W23: 8909 | X23: 0 | Y23: FDIK | Z23: 7500 | AA23: (주)제일좋은솔루션 | AD23: 농협 | AE23: 3486500 | AF23: 64515 | AG23: 3421985 | AH23: =+AE23-AF23-AG23 -> 0
A24: 108-85-35722 | B24: 신성통상에디션ANDZ퍼스트빌 | C24: 2022-08-03 | D24: 13:26:56 | E24: 9440-03**-****-8267 | F24: 78808011 | G24: 비씨 | H24: 39000 | I24: 입금완료 | J24: 승인 | K24: 정상 | L24: 2022-08-08 | M24: CAT | N24: 712781159 | O24: 526 | P24: 38474 | Q24: 11908757 | S24: 비씨 | T24: (0000) 정상완료 | U24: 18991271 | V24: CAT(유선) | W24: 3545 | X24: 0 | Y24: FDIK | Z24: 7500 | AA24: (주)제일좋은솔루션 | AD24: 롯데 | AE24: 521000 | AF24: 11983 | AG24: 509017 | AH24: =+AE24-AF24-AG24 -> 0
A25: 108-85-35722 | B25: 신성통상에디션ANDZ퍼스트빌 | C25: 2022-08-03 | D25: 16:05:17 | E25: 5461-12**-****-6060 | F25: 76655095 | G25: 농협 | H25: 58000 | I25: 입금완료 | J25: 승인 | L25: 2022-08-08 | M25: CAT | N25: 148832581 | O25: 841 | P25: 57159 | Q25: 11908757 | S25: 농협 | T25: (0000) 정상완료 | U25: 18991271 | V25: CAT(유선) | W25: 5272 | X25: 0 | Y25: FDIK | Z25: 7500 | AA25: (주)제일좋은솔루션 | AD25: 비씨 | AE25: 3224000 | AF25: 53790 | AG25: 3170210 | AH25: =+AE25-AF25-AG25 -> 0
A26: 108-85-35722 | B26: 신성통상에디션ANDZ퍼스트빌 | C26: 2022-08-03 | D26: 18:07:19 | E26: 9420-12**-****-5274 | F26: 72639792 | G26: 비씨 | H26: 88000 | I26: 입금완료 | J26: 승인 | K26: 정상 | L26: 2022-08-08 | M26: CAT | N26: 712781159 | O26: 2024 | P26: 85976 | Q26: 11908757 | S26: 비씨 | T26: (0000) 정상완료 | U26: 18991271 | V26: CAT(유선) | W26: 8000 | X26: 0 | Y26: FDIK | Z26: 7500 | AA26: (주)제일좋은솔루션 | AD26: 삼성 | AE26: 1247000 | AF26: 28681 | AG26: 1218319 | AH26: =+AE26-AF26-AG26 -> 0
A27: 108-85-35722 | B27: 신성통상에디션ANDZ퍼스트빌 | C27: 2022-08-03 | D27: 19:06:25 | E27: 4553-25**-****-4172 | F27: 61354239 | G27: 비씨 | H27: 167000 | I27: 입금완료 | J27: 승인 | K27: 정상 | L27: 2022-08-08 | M27: CAT | N27: 712781159 | O27: 3841 | P27: 163159 | Q27: 11908757 | S27: 비씨 | T27: (0000) 정상완료 | U27: 18991271 | V27: CAT(유선) | W27: 15181 | X27: 0 | Y27: FDIK | Z27: 7500 | AA27: (주)제일좋은솔루션 | AD27: 신한 | AE27: 1877500 | AF27: 38534 | AG27: 1838966 | AH27: =+AE27-AF27-AG27 -> 0
A28: 108-85-35722 | B28: 신성통상에디션ANDZ퍼스트빌 | C28: 2022-08-04 | D28: 12:07:58 | E28: 5138-94**-****-7547 | F28: 21318086 | G28: 롯데 | H28: 128000 | I28: 입금완료 | J28: 승인 | K28: 정상 | L28: 2022-08-09 | M28: CAT | N28: 9958307570 | O28: 2944 | P28: 125056 | Q28: 11908757 | S28: 롯데 | T28: (0000) 정상완료 | U28: 18991271 | V28: CAT(유선) | W28: 11636 | X28: 0 | Y28: FDIK | Z28: 7500 | AA28: (주)제일좋은솔루션 | AD28: 외환 | AE28: 928000 | AF28: 20671 | AG28: 907329 | AH28: =+AE28-AF28-AG28 -> 0
A29: 108-85-35722 | B29: 신성통상에디션ANDZ퍼스트빌 | C29: 2022-08-04 | D29: 12:23:48 | E29: 4742-89**-****-7675 | F29: 43095756 | G29: 삼성 | H29: 78000 | I29: 입금완료 | J29: 승인 | K29: 정상 | L29: 2022-08-09 | M29: CAT | N29: 173060897 | O29: 1794 | P29: 76206 | Q29: 11908757 | S29: 삼성 | T29: (0000) 정상완료 | U29: 18991271 | V29: CAT(유선) | W29: 7090 | X29: 0 | Y29: FDIK | Z29: 7500 | AA29: (주)제일좋은솔루션 | AD29: 현대 | AE29: 1534400 | AF29: 35291 | AG29: 1499109 | AH29: =+AE29-AF29-AG29 -> 0
A30: 108-85-35722 | B30: 신성통상에디션ANDZ퍼스트빌 | C30: 2022-08-04 | D30: 13:47:21 | E30: 4092-16**-****-4015 | F30: 47602490 | G30: 농협 | H30: 118000 | I30: 입금완료 | J30: 승인 | L30: 2022-08-09 | M30: CAT | N30: 148832581 | O30: 2714 | P30: 115286 | Q30: 11908757 | S30: 농협 | T30: (0000) 정상완료 | U30: 18991271 | V30: CAT(유선) | W30: 10727 | X30: 0 | Y30: FDIK | Z30: 7500 | AA30: (주)제일좋은솔루션
A31: 108-85-35722 | B31: 신성통상에디션ANDZ퍼스트빌 | C31: 2022-08-04 | D31: 15:52:02 | E31: 6243-31**-****-5710 | F31: 38740161 | G31: 신한 | H31: 119000 | I31: 입금완료 | J31: 승인 | L31: 2022-08-09 | M31: CAT | N31: 0112786827 | O31: 2737 | P31: 116263 | Q31: 11908757 | S31: 신한 | T31: (0000) 정상완료 | U31: 18991271 | V31: CAT(유선) | W31: 10818 | X31: 0 | Y31: FDIK | Z31: 7500 | AA31: (주)제일좋은솔루션
A32: 108-85-35722 | B32: 신성통상에디션ANDZ퍼스트빌 | C32: 2022-08-04 | D32: 16:55:55 | E32: 9441-16**-****-3129 | F32: 49662175 | G32: 농협 | H32: 68000 | I32: 입금완료 | J32: 승인 | L32: 2022-08-09 | M32: CAT | N32: 148832581 | O32: 986 | P32: 67014 | Q32: 11908757 | S32: 농협 | T32: (0000) 정상완료 | U32: 18991271 | V32: CAT(유선) | W32: 6181 | X32: 0 | Y32: FDIK | Z32: 7500 | AA32: (주)제일좋은솔루션
A33: 108-85-35722 | B33: 신성통상에디션ANDZ퍼스트빌 | C33: 2022-08-05 | D33: 12:23:07 | E33: 5424-16**-****-2417 | F33: 56139447 | G33: 농협 | H33: 206000 | I33: 입금완료 | J33: 승인 | L33: 2022-08-10 | M33: CAT | N33: 148832581 | O33: 4738 | P33: 201262 | Q33: 11908757 | S33: 농협 | T33: (0000) 정상완료 | U33: 18991271 | V33: CAT(유선) | W33: 18727 | X33: 0 | Y33: FDIK | Z33: 7500 | AA33: (주)제일좋은솔루션
A34: 108-85-35722 | B34: 신성통상에디션ANDZ퍼스트빌 | C34: 2022-08-05 | D34: 13:08:35 | E34: 5503-47**-****-2613 | F34: 00055356 | G34: 현대 | H34: 118000 | I34: 입금완료 | J34: 승인 | K34: 정상 | L34: 2022-08-10 | M34: CAT | N34: 310963063 | O34: 2714 | P34: 115286 | Q34: 11908757 | S34: 현대 | T34: (0000) 정상완료 | U34: 18991271 | V34: CAT(유선) | W34: 10727 | X34: 0 | Y34: FDIK | Z34: 7500 | AA34: (주)제일좋은솔루션
A35: 108-85-35722 | B35: 신성통상에디션ANDZ퍼스트빌 | C35: 2022-08-05 | D35: 13:29:19 | E35: 5461-11**-****-5150 | F35: 57002257 | G35: 농협 | H35: 69000 | I35: 입금완료 | J35: 승인 | L35: 2022-08-10 | M35: CAT | N35: 148832581 | O35: 1000 | P35: 68000 | Q35: 11908757 | S35: 농협 | T35: (0000) 정상완료 | U35: 18991271 | V35: CAT(유선) | W35: 6272 | X35: 0 | Y35: FDIK | Z35: 7500 | AA35: (주)제일좋은솔루션
A36: 108-85-35722 | B36: 신성통상에디션ANDZ퍼스트빌 | C36: 2022-08-05 | D36: 14:11:08 | E36: 5424-16**-****-4202 | F36: 57471004 | G36: 농협 | H36: 39000 | I36: 입금완료 | J36: 승인 | L36: 2022-08-10 | M36: CAT | N36: 148832581 | O36: 897 | P36: 38103 | Q36: 11908757 | S36: 농협 | T36: (0000) 정상완료 | U36: 18991271 | V36: CAT(유선) | W36: 3545 | X36: 0 | Y36: FDIK | Z36: 7500 | AA36: (주)제일좋은솔루션
A37: 108-85-35722 | B37: 신성통상에디션ANDZ퍼스트빌 | C37: 2022-08-05 | D37: 14:57:34 | E37: 9440-03**-****-7074 | F37: 72503402 | G37: 비씨 | H37: 39000 | I37: 입금완료 | J37: 승인 | K37: 정상 | L37: 2022-08-10 | M37: CAT | N37: 712781159 | O37: 526 | P37: 38474 | Q37: 11908757 | S37: 비씨 | T37: (0000) 정상완료 | U37: 18991271 | V37: CAT(유선) | W37: 3545 | X37: 0 | Y37: FDIK | Z37: 7500 | AA37: (주)제일좋은솔루션
A38: 108-85-35722 | B38: 신성통상에디션ANDZ퍼스트빌 | C38: 2022-08-05 | D38: 16:33:34 | E38: 4854-79**-****-0902 | F38: 59099749 | G38: 농협 | H38: 39000 | I38: 입금완료 | J38: 승인 | L38: 2022-08-10 | M38: CAT | N38: 148832581 | O38: 565 | P38: 38435 | Q38: 11908757 | S38: 농협 | T38: (0000) 정상완료 | U38: 18991271 | V38: CAT(유선) | W38: 3545 | X38: 0 | Y38: FDIK | Z38: 7500 | AA38: (주)제일좋은솔루션
A39: 108-85-35722 | B39: 신성통상에디션ANDZ퍼스트빌 | C39: 2022-08-05 | D39: 17:44:39 | E39: 4330-28**-****-4312 | F39: 00110978 | G39: 현대 | H39: 198000 | I39: 입금완료 | J39: 승인 | K39: 정상 | L39: 2022-08-10 | M39: CAT | N39: 310963063 | O39: 4554 | P39: 193446 | Q39: 11908757 | S39: 현대 | T39: (0000) 정상완료 | U39: 18991271 | V39: CAT(유선) | W39: 18000 | X39: 0 | Y39: FDIK | Z39: 7500 | AA39: (주)제일좋은솔루션
A40: 108-85-35722 | B40: 신성통상에디션ANDZ퍼스트빌 | C40: 2022-08-05 | D40: 18:15:56 | E40: 4033-02**-****-7919 | F40: 00127206 | G40: 현대 | H40: 69000 | I40: 입금완료 | J40: 승인 | K40: 정상 | L40: 2022-08-10 | M40: CAT | N40: 310963063 | O40: 1587 | P40: 67413 | Q40: 11908757 | S40: 현대 | T40: (0000) 정상완료 | U40: 18991271 | V40: CAT(유선) | W40: 6272 | X40: 0 | Y40: FDIK | Z40: 7500 | AA40: (주)제일좋은솔루션
A41: 108-85-35722 | B41: 신성통상에디션ANDZ퍼스트빌 | C41: 2022-08-06 | D41: 12:33:58 | E41: 9411-17**-****-3499 | F41: 66120079 | G41: 농협 | H41: 118000 | I41: 입금완료 | J41: 승인 | L41: 2022-08-10 | M41: CAT | N41: 148832581 | O41: 2714 | P41: 115286 | Q41: 11908757 | S41: 농협 | T41: (0000) 정상완료 | U41: 18991271 | V41: CAT(유선) | W41: 10727 | X41: 0 | Y41: FDIK | Z41: 7500 | AA41: (주)제일좋은솔루션
...

Sheet 임대을정산
A2: 1. 월 유통망별 매출집계
A51: 2. 임차관리비 정산

Sheet 특정매입정산
A2: 전달 25일~ | C2: 1. 공급분미수관리
D3: - FONE 매입/반품 금액 확인 후 백화점 EDI에서 발주 | AC3: **백화점 정산 - 세금계산서 금액 산출
R6: 당월확정금액 | S6: 19240301
R7: 조정잔액 * 1.1 | S7: -88
R8: 매입/반품 설정 금액 | S8: =+S6+S7 -> 19240213
D12: **업체EDI
S18: 재고 현재 비슷하여 두 마진율에 50:50으로 매입 설정
V19: 마진율 반영한 매입반품금액
S20: 마진율 | T20: 33 | U20: =+S8/2 -> 9620106.5 | V20: =+U20*(100/(100-T20)) -> 14358368
T21: 25 | U21: =+S8-U20 -> 9620106.5 | V21: =+U21*(100/(100-T21)) -> 12826809
U22: =+U21+U20 -> 19240213 | V22: =+V21+V20 -> 27185177
W55: =8745557+8745440 -> 17490997
A61: 1일~ | C61: 2. 월 유통망별 매출집계
D62: - 업체 EDI에 맞추어 F-ONE 금액조정
H77: **FONE 할인/마진율 등록
D78: ** 업체 EDI
Q96: **마진별 판매금액이 다른경우, 백화점 EDI에 맞추어 조정됨
C111: 3. 세금계산서 확인
D112: - 공급분/ 판매분
D122: 1) 공급분
D124: **업체 발행 세금계산서
D171: 2) 판매분

Sheet 온라인정산
A2: 1. 월 유통망별 매출집계 및 업로드
B3: - 실매출금액 정산
B4: - 배송비는 기타매출 정산
Q10: 실매출금액 | R10: 7874250
Q11: 선불배송비 | R11: 123000
Q12: 기타정산/공제 | R12: 26100
Q13: 세금계산서 발행금액 | R13: 1018651
Q14: 지급예정액 | R14: =+R10+R11-R13 -> 6978599
B23: 1) 업체EDI
B79: 2) 비용처리
B80: - 매출 수수료 및 패널티 등의 비용 처리

Sheet 매출마감(BBT003)
A1: 아산퍼스트빌리지 직영점 월마감
A2: 2022년 08월
B3: 일 자 별 | C3: EA | D3: 합 계
B4: 총 매출 | C4: =아산퍼스트빌!P37 -> 15451400 | D4: =아산퍼스트빌!B37 -> 15451400
B5: 구성비 | C5: 1 | D5: =D4/D4 -> 1
A6: 매출 | B6: 매출형태별 | C6: BBT003 | D6: 합 계
B7: 전산금액 | C7: =C4 -> 15451400 | D7: =D4 -> 15451400
B8: 현 금 | C8: =아산퍼스트빌!C37 -> 546000 | D8: =아산퍼스트빌!C37 -> 546000
B9: 카 드 | C9: =아산퍼스트빌!N37 -> 14905400 | D9: =D7-D8 -> 14905400
B10: 상품권 | J10: `
B11: 합 계 | C11: =SUM(C8:C10) -> 15451400 | D11: =SUM(D8:D10) -> 15451400
A12: 매출 | B12: 카드사별 | C12: BBT003 | D12: 합 계
B13: 비씨 | C13: =아산퍼스트빌!E37 -> 3224000 | D13: =C13 -> 3224000
B14: 신한 | C14: =아산퍼스트빌!F37 -> 1877500 | D14: =C14 -> 1877500
B15: 삼성 | C15: =아산퍼스트빌!G37 -> 1247000 | D15: =C15 -> 1247000
B16: 현대 | C16: =아산퍼스트빌!H37 -> 1534400 | D16: =C16 -> 1534400
B17: 롯데 | C17: =아산퍼스트빌!I37 -> 521000 | D17: =C17 -> 521000
B18: KB국민 | C18: =아산퍼스트빌!J37 -> 2087000 | D18: =C18 -> 2087000
B19: 하나 | C19: =아산퍼스트빌!K37 -> 928000 | D19: =C19 -> 928000 | H19: KB국민 | I19: 2087000 | J19: 2048444 | K19: 38556 | L19: =I19-J19-K19 -> 0 | M19: =K19/I19 -> 0.018474365
B20: 농협 | C20: =아산퍼스트빌!L37 -> 3486500 | D20: =C20 -> 3486500 | H20: 농협 | I20: 3486500 | J20: 3421985 | K20: 64515 | L20: =I20-J20-K20 -> 0 | M20: =K20/I20 -> 0.018504231
B21: 합 계 | C21: =SUM(C13:C20) -> 14905400 | D21: =SUM(D13:D20) -> 14905400 | H21: 롯데 | I21: 521000 | J21: 509017 | K21: 11983 | L21: =I21-J21-K21 -> 0 | M21: =K21/I21 -> 0.023
A22: 카드 | B22: 구 분 | C22: BBT003 합계 | D22: BBT003 합계 | H22: 비씨 | I22: 3224000 | J22: 3170210 | K22: 53790 | L22: =I22-J22-K22 -> 0 | M22: =K22/I22 -> 0.016684243
A23: 비씨 | B23: 카드수수료 | C23: =K39 -> 53790 | D23: =K39 -> 53790 | H23: 삼성 | I23: 1247000 | J23: 1218319 | K23: 28681 | L23: =I23-J23-K23 -> 0 | M23: =K23/I23 -> 0.023
B24: 입금예정액 | C24: =J39 -> 3170210 | D24: =J39 -> 3170210 | H24: 신한 | I24: 1877500 | J24: 1838966 | K24: 38534 | L24: =I24-J24-K24 -> 0 | M24: =K24/I24 -> 0.020524101
B25: 합 계 | C25: =+C24+C23 -> 3224000 | D25: =+D24+D23 -> 3224000 | E25: =D13 -> 3224000 | F25: =D25-E25 -> 0 | H25: 외환 | I25: 928000 | J25: 907329 | K25: 20671 | L25: =I25-J25-K25 -> 0 | M25: =K25/I25 -> 0.022274784
A26: 신한 | B26: 카드수수료 | C26: =K41 -> 38534 | D26: =K41 -> 38534 | H26: 현대 | I26: 1534400 | J26: 1499109 | K26: 35291 | L26: =I26-J26-K26 -> 0 | M26: =K26/I26 -> 0.02299987
B27: 입금예정액 | C27: =J41 -> 1838966 | D27: =J41 -> 1838966
B28: 합 계 | C28: =C26+C27 -> 1877500 | D28: =+D27+D26 -> 1877500 | E28: =D14 -> 1877500 | F28: =D28-E28 -> 0
A29: 삼성 | B29: 카드수수료 | C29: =K40 -> 28681 | D29: =K40 -> 28681
B30: 입금예정액 | C30: =J40 -> 1218319 | D30: =J40 -> 1218319
B31: 합 계 | C31: =C29+C30 -> 1247000 | D31: =+D30+D29 -> 1247000 | E31: =D15 -> 1247000 | F31: =D31-E31 -> 0
A32: 현대 | B32: 카드수수료 | C32: =K43 -> 35291 | D32: =K43 -> 35291
B33: 입금예정액 | C33: =J43 -> 1499109 | D33: =J43 -> 1499109
B34: 합 계 | C34: =C32+C33 -> 1534400 | D34: =+D33+D32 -> 1534400 | E34: =D16 -> 1534400 | F34: =D34-E34 -> 0
A35: 롯데 | B35: 카드수수료 | C35: =K38 -> 11983 | D35: =K38 -> 11983 | G35: 카드사 | H35: 매출합계금액 | I35: 매입액 | J35: 입금예정금액 | K35: 수수료
B36: 입금예정액 | C36: =J38 -> 509017 | D36: =J38 -> 509017 | G36: KB국민 | H36: 2087000 | J36: 2048444 | K36: 38556 | L36: =J36+K36 -> 2087000 | M36: =H36-L36 -> 0
B37: 합 계 | C37: =C35+C36 -> 521000 | D37: =D35+D36 -> 521000 | E37: =D17 -> 521000 | F37: =D37-E37 -> 0 | G37: 농협 | H37: 3486500 | J37: 3421985 | K37: 64515 | L37: =J37+K37 -> 3486500 | M37: =H37-L37 -> 0
A38: KB국민 | B38: 카드수수료 | C38: =K36 -> 38556 | D38: =K36 -> 38556 | G38: 롯데 | H38: 521000 | J38: 509017 | K38: 11983 | L38: =J38+K38 -> 521000 | M38: =H38-L38 -> 0
B39: 입금예정액 | C39: =J36 -> 2048444 | D39: =J36 -> 2048444 | G39: 비씨 | H39: 3224000 | J39: 3170210 | K39: 53790 | L39: =J39+K39 -> 3224000 | M39: =H39-L39 -> 0
B40: 합 계 | C40: =C38+C39 -> 2087000 | D40: =D38+D39 -> 2087000 | E40: =D18 -> 2087000 | F40: =D40-E40 -> 0 | G40: 삼성 | H40: 1247000 | J40: 1218319 | K40: 28681 | L40: =J40+K40 -> 1247000 | M40: =H40-L40 -> 0
...

Sheet 아산퍼스트빌
A1: 아산퍼스트빌점(직영) 2022년 8월 판매일보
B2: EDITION
B3: (사업자 : 108-85-35722)
A4: 일자 | B4: FONE | C4: 현 금 | D4: 입금액 | E4: 카드사별 매출(머니온) | O4: 상품권 | P4: 계 | Q4: 비 고
B5: BBT003 | E5: 비씨 | F5: 신한 | G5: 삼성 | H5: 현대 | I5: 롯데 | J5: KB국민 | K5: 외환 하나 | L5: 농협 | M5: 기타 | N5: 소계
A6: 1 | B6: 324000 | E6: 288000 | F6: 103000 | G6: 227000 | H6: 284000 | I6: 69000 | J6: 29000 | N6: =SUM(E6:M6) -> 1000000 | P6: =C6+N6 -> 1000000 | R6: =B6-P6 -> -676000
A7: 2 | B7: 575500 | E7: 39000 | F7: 139000 | H7: 69000 | K7: 327000 | L7: 49000 | N7: =SUM(E7:M7) -> 623000 | P7: =C7+N7 -> 623000 | R7: =B7-P7 -> -47500
A8: 3 | B8: 545000 | E8: 294000 | F8: 268000 | L8: 156000 | N8: =SUM(E8:M8) -> 718000 | P8: =C8+N8 -> 718000 | R8: =B8-P8 -> -173000
A9: 4 | B9: 501000 | F9: 119000 | G9: 78000 | I9: 128000 | L9: 186000 | N9: =SUM(E9:M9) -> 511000 | P9: =C9+N9 -> 511000 | R9: =B9-P9 -> -10000
A10: 5 | B10: 737000 | E10: 39000 | H10: 385000 | L10: 353000 | N10: =SUM(E10:M10) -> 777000 | P10: =C10+N10 -> 777000 | R10: =B10-P10 -> -40000
A11: 6 | B11: 642000 | H11: 226000 | J11: 254000 | K11: 29000 | L11: 177000 | N11: =SUM(E11:M11) -> 686000 | P11: =C11+N11 -> 686000 | R11: =B11-P11 -> -44000
A12: 7 | B12: 1010000 | E12: 367000 | G12: 58000 | H12: 169000 | J12: 137000 | L12: 118000 | N12: =SUM(E12:M12) -> 849000 | P12: =C12+N12 -> 849000 | R12: =B12-P12 -> 161000
A13: 8 | B13: 226000 | F13: 236000 | G13: 153000 | H13: 123000 | N13: =SUM(E13:M13) -> 512000 | P13: =C13+N13 -> 512000 | R13: =B13-P13 -> -286000
A14: 9 | B14: 166000 | E14: 241000 | N14: =SUM(E14:M14) -> 241000 | P14: =C14+N14 -> 241000 | R14: =B14-P14 -> -75000
A15: 10 | B15: 216000 | J15: 49000 | L15: 98000 | M15: - | N15: =SUM(E15:M15) -> 147000 | P15: =C15+N15 -> 147000 | R15: =B15-P15 -> 69000
A16: 11 | B16: 196000 | E16: 118000 | L16: 39000 | M16: - | N16: =SUM(E16:M16) -> 157000 | P16: =C16+N16 -> 157000 | R16: =B16-P16 -> 39000
A17: 12 | B17: 324000 | E17: 39000 | F17: 74500 | G17: 98000 | H17: 118000 | J17: 29000 | L17: 552500 | M17: - | N17: =SUM(E17:M17) -> 911000 | P17: =C17+N17 -> 911000 | R17: =B17-P17 -> -587000
A18: 13 | B18: 1105000 | E18: 68000 | F18: 88000 | G18: 156000 | J18: 294000 | L18: 245000 | M18: - | N18: =SUM(E18:M18) -> 851000 | P18: =C18+N18 -> 851000 | R18: =B18-P18 -> 254000
A19: 14 | B19: 947800 | C19: 29000 | E19: 227000 | F19: 49000 | G19: 64000 | I19: 160000 | J19: 172000 | K19: 180000 | L19: 108000 | M19: - | N19: =SUM(E19:M19) -> 960000 | P19: =C19+N19 -> 989000 | R19: =B19-P19 -> -41200
A20: 15 | B20: 1050500 | E20: 206000 | I20: 39000 | J20: 589000 | M20: - | N20: =SUM(E20:M20) -> 834000 | P20: =C20+N20 -> 834000 | R20: =B20-P20 -> 216500
A21: 16 | B21: 293000 | E21: 127000 | F21: 39000 | J21: 98000 | M21: - | N21: =SUM(E21:M21) -> 264000 | P21: =C21+N21 -> 264000 | R21: =B21-P21 -> 29000
A22: 17 | B22: 509000 | G22: 39000 | L22: 150000 | M22: - | N22: =SUM(E22:M22) -> 189000 | P22: =C22+N22 -> 189000 | R22: =B22-P22 -> 320000
A23: 18 | B23: 59000 | G23: 160000 | I23: -160000 | M23: - | N23: =SUM(E23:M23) -> 0 | P23: =C23+N23 -> 0 | R23: =B23-P23 -> 59000
A24: 19 | B24: 167000 | C24: 177000 | G24: 39000 | M24: - | N24: =SUM(E24:M24) -> 39000 | P24: =C24+N24 -> 216000 | R24: =B24-P24 -> -49000
A25: 20 | B25: 807000 | E25: 353000 | F25: 161000 | I25: 187000 | J25: 39000 | L25: 266000 | M25: - | N25: =SUM(E25:M25) -> 1006000 | P25: =C25+N25 -> 1006000 | R25: =B25-P25 -> -199000
A26: 21 | B26: 916000 | F26: 149000 | H26: 39000 | I26: 59000 | J26: 69000 | L26: 158000 | M26: - | N26: =SUM(E26:M26) -> 474000 | P26: =C26+N26 -> 474000 | R26: =B26-P26 -> 442000
A27: 22 | B27: 117000 | E27: 39000 | L27: 59000 | M27: - | N27: =SUM(E27:M27) -> 98000 | P27: =C27+N27 -> 98000 | R27: =B27-P27 -> 19000
A28: 23 | B28: 318800 | E28: 176000 | G28: 58000 | K28: 187000 | L28: 60000 | M28: - | N28: =SUM(E28:M28) -> 481000 | P28: =C28+N28 -> 481000 | R28: =B28-P28 -> -162200
A29: 24 | B29: 78000 | M29: - | N29: =SUM(E29:M29) -> 0 | P29: =C29+N29 -> 0 | R29: =B29-P29 -> 78000
A30: 25 | B30: 166000 | H30: 69000 | L30: 29000 | M30: - | N30: =SUM(E30:M30) -> 98000 | P30: =C30+N30 -> 98000 | R30: =B30-P30 -> 68000
A31: 26 | B31: 156000 | E31: 78000 | F31: 59000 | M31: - | N31: =SUM(E31:M31) -> 137000 | P31: =C31+N31 -> 137000 | R31: =B31-P31 -> 19000
A32: 27 | B32: 632000 | E32: 39000 | F32: 59000 | G32: 78000 | J32: 79000 | L32: 425000 | M32: - | N32: =SUM(E32:M32) -> 680000 | P32: =C32+N32 -> 680000 | R32: =B32-P32 -> -48000
A33: 28 | B33: 1560000 | C33: 340000 | E33: 407000 | F33: 334000 | G33: 39000 | I33: 39000 | K33: 39000 | L33: 258000 | M33: - | N33: =SUM(E33:M33) -> 1116000 | P33: =C33+N33 -> 1456000 | R33: =B33-P33 -> 104000
A34: 29 | B34: 68000 | M34: - | N34: =SUM(E34:M34) -> 0 | P34: =C34+N34 -> 0 | R34: =B34-P34 -> 68000
A35: 30 | B35: 315000 | E35: 79000 | H35: 49000 | K35: 59000 | M35: - | N35: =SUM(E35:M35) -> 187000 | P35: =C35+N35 -> 187000 | R35: =B35-P35 -> 128000
A36: 31 | B36: 723800 | H36: 3400 | J36: 249000 | K36: 107000 | N36: =SUM(E36:M36) -> 359400 | P36: =C36+N36 -> 359400 | R36: =B36-P36 -> 364400
A37: 계 | B37: =SUM(B6:B36) -> 15451400 | C37: =SUM(C6:C36) -> 546000 | E37: =SUM(E6:E36) -> 3224000 | F37: =SUM(F6:F36) -> 1877500 | G37: =SUM(G6:G36) -> 1247000 | H37: =SUM(H6:H36) -> 1534400 | I37: =SUM(I6:I36) -> 521000 | J37: =SUM(J6:J36) -> 2087000 | K37: =SUM(K6:K36) -> 928000 | L37: =SUM(L6:L36) -> 3486500 | ... N37: =SUM(N6:N36) -> 14905400 | P37: =SUM(P6:P36) -> 15451400 | R37: =SUM(R6:R36) -> 0 | S37: > Fone과 카드사 일별매출 차이 있으나, 토탈은 같음.
E38: =E44 -> 3224000 | F38: =E46 -> 1877500 | G38: =E45 -> 1247000 | H38: =E48 -> 1534400 | I38: =E43 -> 521000 | J38: =E41 -> 2087000 | K38: =E47 -> 928000 | L38: =E42 -> 3486500 | P38: =B37-P37 -> 0
E39: =E37-E38 -> 0 | F39: =F37-F38 -> 0 | G39: =G37-G38 -> 0 | H39: =H37-H38 -> 0 | I39: =I37-I38 -> 0 | J39: =J37-J38 -> 0 | K39: =K37-K38 -> 0 | L39: =L37-L38 -> 0
D41: KB국민 | E41: 2087000
...

Sheet 입금(BBT003)
J1: =+G1 -> 0 | K1: =+G1-J1 -> 0
B2: 브랜드 | C2: 매장ID | D2: 매장명 | E2: 입금일자 | F2: 가상계좌번호 | G2: 입금금액 | H2: 비고 | J2: 7월분 | K2: 8월분
B3: 합 계 | G3: 24753334
B4: N | C4: BBT003 | D4: 아산 퍼스트빌리지점 | E4: 20220801 | F4: 12991558828637 | G4: 133849 | H4: KB92318201 | J4: =+G4 -> 133849 | L4: =SUBTOTAL(9,J4:K4) -> 133849 | M4: =G4=L4 -> TRUE | N4: =G4-L4 -> 0
B5: N | C5: BBT003 | D5: 아산 퍼스트빌리지점 | E5: 20220802 | F5: 12991558824137 | G5: 116230 | H5: 신한11278682 | J5: =+G5 -> 116230 | L5: =SUBTOTAL(9,J5:K5) -> 116230 | M5: =G5=L5 -> TRUE | N5: =G5-L5 -> 0
B6: N | C6: BBT003 | D6: 아산 퍼스트빌리지점 | E6: 20220802 | F6: 12991558830237 | G6: 163159 | H6: NH14883258 | J6: =+G6 -> 163159 | L6: =SUBTOTAL(9,J6:K6) -> 163159 | M6: =G6=L6 -> TRUE | N6: =G6-L6 -> 0
B7: N | C7: BBT003 | D7: 아산 퍼스트빌리지점 | E7: 20220802 | F7: 12991558825737 | G7: 76206 | H7: 삼성173060897 | J7: =+G7 -> 76206 | L7: =SUBTOTAL(9,J7:K7) -> 76206 | M7: =G7=L7 -> TRUE | N7: =G7-L7 -> 0
B8: N | C8: BBT003 | D8: 아산 퍼스트빌리지점 | E8: 20220802 | F8: 12991558825737 | G8: 47873 | H8: 삼성173060897 | J8: =+G8 -> 47873 | L8: =SUBTOTAL(9,J8:K8) -> 47873 | M8: =G8=L8 -> TRUE | N8: =G8-L8 -> 0
B9: N | C9: BBT003 | D9: 아산 퍼스트빌리지점 | E9: 20220802 | F9: 12991558827037 | G9: 57643 | H9: 롯데9958307570 | J9: =+G9 -> 57643 | L9: =SUBTOTAL(9,J9:K9) -> 57643 | M9: =G9=L9 -> TRUE | N9: =G9-L9 -> 0
B10: N | C10: BBT003 | D10: 아산 퍼스트빌리지점 | E10: 20220803 | F10: 12991558824137 | G10: 372237 | H10: 신한11278682 | J10: =+G10 -> 372237 | L10: =SUBTOTAL(9,J10:K10) -> 372237 | M10: =G10=L10 -> TRUE | N10: =G10-L10 -> 0
B11: N | C11: BBT003 | D11: 아산 퍼스트빌리지점 | E11: 20220803 | F11: 12991558829237 | G11: 202426 | H11: 하나994444693 | J11: =+G11 -> 202426 | L11: =SUBTOTAL(9,J11:K11) -> 202426 | M11: =G11=L11 -> TRUE | N11: =G11-L11 -> 0
B12: N | C12: BBT003 | D12: 아산 퍼스트빌리지점 | E12: 20220803 | F12: 12991558828637 | G12: 152412 | H12: KB92318201 | J12: =+G12 -> 152412 | L12: =SUBTOTAL(9,J12:K12) -> 152412 | M12: =G12=L12 -> TRUE | N12: =G12-L12 -> 0
B13: N | C13: BBT003 | D13: 아산 퍼스트빌리지점 | E13: 20220803 | F13: 12991558823437 | G13: 675779 | H13: 712781159BC | J13: =+G13 -> 675779 | L13: =SUBTOTAL(9,J13:K13) -> 675779 | M13: =G13=L13 -> TRUE | N13: =G13-L13 -> 0
B14: N | C14: BBT003 | D14: 아산 퍼스트빌리지점 | E14: 20220803 | F14: 12991558830237 | G14: 732982 | H14: NH14883258 | J14: =+G14 -> 732982 | L14: =SUBTOTAL(9,J14:K14) -> 732982 | M14: =G14=L14 -> TRUE | N14: =G14-L14 -> 0
B15: N | C15: BBT003 | D15: 아산 퍼스트빌리지점 | E15: 20220803 | F15: 12991558825737 | G15: 155343 | H15: 삼성173060897 | J15: =+G15 -> 155343 | L15: =SUBTOTAL(9,J15:K15) -> 155343 | M15: =G15=L15 -> TRUE | N15: =G15-L15 -> 0
... B18: N | C18: BBT003 | D18: 아산 퍼스트빌리지점 | E18: 20220803 | F18: 12991558826337 | G18: 408142 | H18: 현310963063 | J18: =+G18 -> 408142 | L18: =SUBTOTAL(9,J18:K18) -> 408142 | M18: =G18=L18 -> TRUE | N18: =G18-L18 -> 0
B19: N | C19: BBT003 | D19: 아산 퍼스트빌리지점 | E19: 20220804 | F19: 12991558824137 | G19: 101143 | H19: 신한11278682 | K19: =+G19-J19 -> 101143 | L19: =SUBTOTAL(9,J19:K19) -> 101143 | M19: =G19=L19 -> TRUE | N19: =G19-L19 -> 0
B20: N | C20: BBT003 | D20: 아산 퍼스트빌리지점 | E20: 20220804 | F20: 12991558823437 | G20: 283994 | H20: 712781159BC | K20: =+G20-J20 -> 283994 | L20: =SUBTOTAL(9,J20:K20) -> 283994 | M20: =G20=L20 -> TRUE | N20: =G20-L20 -> 0
B21: N | C21: BBT003 | D21: 아산 퍼스트빌리지점 | E21: 20220804 | F21: 12991558828637 | G21: 28333 | H21: KB92318201 | K21: =+G21-J21 -> 28333 | L21: =SUBTOTAL(9,J21:K21) -> 28333 | M21: =G21=L21 -> TRUE | N21: =G21-L21 -> 0
B22: N | C22: BBT003 | D22: 아산 퍼스트빌리지점 | E22: 20220804 | F22: 12991558825737 | G22: 221779 | H22: 삼성173060897 | K22: =+G22-J22 -> 221779 | L22: =SUBTOTAL(9,J22:K22) -> 221779 | M22: =G22=L22 -> TRUE | N22: =G22-L22 -> 0
B23: N | C23: BBT003 | D23: 아산 퍼스트빌리지점 | E23: 20220804 | F23: 12991558827037 | G23: 67413 | H23: 롯데9958307570 | K23: =+G23-J23 -> 67413 | L23: =SUBTOTAL(9,J23:K23) -> 67413 | M23: =G23=L23 -> TRUE | N23: =G23-L23 -> 0
B24: N | C24: BBT003 | D24: 아산 퍼스트빌리지점 | E24: 20220804 | F24: 12991558826337 | G24: 277468 | H24: 현310963063 | K24: =+G24-J24 -> 277468 | L24: =SUBTOTAL(9,J24:K24) -> 277468 | M24: =G24=L24 -> TRUE | N24: =G24-L24 -> 0
B25: N | C25: BBT003 | D25: 아산 퍼스트빌리지점 | E25: 20220805 | F25: 12991558824137 | G25: 136603 | H25: 신한11278682 | K25: =+G25-J25 -> 136603 | L25: =SUBTOTAL(9,J25:K25) -> 136603 | M25: =G25=L25 -> TRUE | N25: =G25-L25 -> 0
B26: N | C26: BBT003 | D26: 아산 퍼스트빌리지점 | E26: 20220805 | F26: 12991558829237 | G26: 319479 | H26: 하나994444693 | K26: =+G26-J26 -> 319479 | L26: =SUBTOTAL(9,J26:K26) -> 319479 | M26: =G26=L26 -> TRUE | N26: =G26-L26 -> 0
B27: N | C27: BBT003 | D27: 아산 퍼스트빌리지점 | E27: 20220805 | F27: 12991558823437 | G27: 38103 | H27: 712781159BC | K27: =+G27-J27 -> 38103 | L27: =SUBTOTAL(9,J27:K27) -> 38103 | M27: =G27=L27 -> TRUE | N27: =G27-L27 -> 0
B28: N | C28: BBT003 | D28: 아산 퍼스트빌리지점 | E28: 20220805 | F28: 12991558830237 | G28: 47873 | H28: NH14883258 | K28: =+G28-J28 -> 47873 | L28: =SUBTOTAL(9,J28:K28) -> 47873 | M28: =G28=L28 -> TRUE | N28: =G28-L28 -> 0
B29: N | C29: BBT003 | D29: 아산 퍼스트빌리지점 | E29: 20220805 | F29: 12991558826337 | G29: 67413 | H29: 현310963063 | K29: =+G29-J29 -> 67413 | L29: =SUBTOTAL(9,J29:K29) -> 67413 | M29: =G29=L29 -> TRUE | N29: =G29-L29 -> 0
B30: N | C30: BBT003 | D30: 아산 퍼스트빌리지점 | E30: 20220808 | F30: 12991558824137 | G30: 261836 | H30: 신한11278682 | K30: =+G30-J30 -> 261836 | L30: =SUBTOTAL(9,J30:K30) -> 261836 | M30: =G30=L30 -> TRUE | N30: =G30-L30 -> 0
... B90: N | C90: BBT003 | D90: 아산 퍼스트빌리지점 | E90: 20220831 | F90: 12991558827037 | G90: 38103 | H90: 롯데9958307570 | K90: =+G90-J90 -> 38103 | L90: =SUBTOTAL(9,J90:K90) -> 38103 | M90: =G90=L90 -> TRUE | N90: =G90-L90 -> 0
B91: N | C91: BBT003 | D91: 아산 퍼스트빌리지점 | E91: 20220831 | F91: 12991558831937 | G91: 546000 | H91: 이재성 | L91: =SUBTOTAL(9,J91:K91) -> 0 | M91: =G91=L91 -> FALSE | N91: =G91-L91 -> 546000
G92: =SUBTOTAL(9,G4:G90) -> 17545902 | J92: =SUBTOTAL(9,J4:J91) -> 3467599 | K92: =SUBTOTAL(9,K4:K90) -> 14078303 | L92: =+G92-J92-K92 -> 0
N98: =G98-L98 -> 0
L99: 카드사 | M99: 6월 | N99: =G99-L99 -> #VALUE! | O99: 입금예정금액
L100: KB국민 | M100: 2476797 | N100: =G100-L100 -> #VALUE! | O100: 2859598 | P100: 1038143103
L101: 농협 | M101: 2794206 | N101: =G101-L101 -> #VALUE! | O101: 3313136 | P101: 1048639742
L102: 롯데 | M102: 945640 | N102: =G102-L102 -> #VALUE! | O102: 945640 | P102: 1208154231
L103: 비씨 | M103: 3389178 | N103: =G103-L103 -> #VALUE! | O103: 4337398 | P103: 2028117047
L104: 삼성 | M104: 3166752 | N104: =G104-L104 -> #VALUE! | O104: 3689447 | P104: 1038117885
L105: 신한 | M105: 2782647 | N105: =G105-L105 -> #VALUE! | O105: 3339577 | P105: 1048172014
L106: 외환 | M106: 1234400 | N106: =G106-L106 -> #VALUE! | O106: 1591323 | P106: 1168129617
...

Sheet 머니온(아산)
A1: * 대상기간 : 2022년 08월 01일 ~ 2022년 08월 31일
A2: * 지점명 : 에디션ANDZ아산퍼스트빌(본사)
A4: 사업자번호 | B4: 상호 | C4: 거래일자 | D4: 거래시간 | E4: 카드번호 | F4: 승인번호 | G4: 매입사 | H4: 금액 | I4: 처리현황 | J4: 거래유형 | K4: 반송사유 | L4: 입금예정 | M4: 단말기종류 | N4: 가맹점번호 | O4: 수수료 | P4: 입금예정액 | Q4: 단말기 | R4: 점코드 | S4: 발급사 | T4: 거래결과 | U4: 대리점연락처 | V4: 단말기구분 | W4: 세금 | X4: 비과세금액 | Y4: 밴CODE | Z4: 그룹코드 | AA4: 대리점 | AB4: 취소여부 | AE4: 행 레이블 | AF4: 합계 : 금액 | AG4: 합계 : 입금예정액 | AH4: 합계 : 수수료
A5: 108-85-35722 | B5: 신성통상에디션ANDZ퍼스트빌 | C5: 2022-08-01 | D5: 11:07:39 | E5: 5107-37**-****-7340 | F5: 46315411 | G5: 신한 | H5: 64000 | I5: 입금완료 | J5: 승인 | L5: 2022-08-04 | M5: CAT | N5: 0112786827 | O5: 960 | P5: 63040 | Q5: 11908757 | S5: 신한 | T5: (0000) 정상완료 | U5: 18991271 | V5: CAT(유선) | W5: 5818 | X5: 0 | Y5: FDIK | Z5: 7500 | AA5: (주)제일좋은솔루션 | AE5: KB국민 | AF5: 2087000 | AG5: 2048444 | AH5: 38556
A6: 108-85-35722 | B6: 신성통상에디션ANDZ퍼스트빌 | C6: 2022-08-01 | D6: 14:54:10 | E6: 4273-52**-****-3564 | F6: 78480180 | G6: 비씨 | H6: 170000 | I6: 입금완료 | J6: 승인 | K6: 정상 | L6: 2022-08-04 | M6: CAT | N6: 712781159 | O6: 2295 | P6: 167705 | Q6: 11908757 | S6: 비씨 | T6: (0000) 정상완료 | U6: 18991271 | V6: CAT(유선) | W6: 15454 | X6: 0 | Y6: FDIK | Z6: 7500 | AA6: (주)제일좋은솔루션 | AE6: 농협 | AF6: 3486500 | AG6: 3421985 | AH6: 64515
A7: 108-85-35722 | B7: 신성통상에디션ANDZ퍼스트빌 | C7: 2022-08-01 | D7: 15:03:46 | E7: 9409-15**-****-4623 | F7: 64103155 | G7: 롯데 | H7: 69000 | I7: 입금완료 | J7: 승인 | K7: 정상 | L7: 2022-08-04 | M7: CAT | N7: 9958307570 | O7: 1587 | P7: 67413 | Q7: 11908757 | S7: 롯데 | T7: (0000) 정상완료 | U7: 18991271 | V7: CAT(유선) | W7: 6272 | X7: 0 | Y7: FDIK | Z7: 7500 | AA7: (주)제일좋은솔루션 | AE7: 롯데 | AF7: 521000 | AG7: 509017 | AH7: 11983
A8: 108-85-35722 | B8: 신성통상에디션ANDZ퍼스트빌 | C8: 2022-08-01 | D8: 15:21:37 | E8: 4033-02**-****-7317 | F8: 00327228 | G8: 현대 | H8: 88000 | I8: 입금완료 | J8: 승인 | K8: 정상 | L8: 2022-08-04 | M8: CAT | N8: 310963063 | O8: 2024 | P8: 85976 | Q8: 11908757 | S8: 현대 | T8: (0000) 정상완료 | U8: 18991271 | V8: CAT(유선) | W8: 8000 | X8: 0 | Y8: FDIK | Z8: 7500 | AA8: (주)제일좋은솔루션 | AE8: 비씨 | AF8: 3224000 | AG8: 3093027 | AH8: 51973
A9: 108-85-35722 | B9: 신성통상에디션ANDZ퍼스트빌 | C9: 2022-08-01 | D9: 15:31:22 | E9: 4579-72**-****-7079 | F9: 30034431 | G9: KB국민 | H9: 29000 | I9: 입금완료 | J9: 승인 | K9: 정상 | L9: 2022-08-04 | M9: CAT | N9: 00092318201 | O9: 667 | P9: 28333 | Q9: 11908757 | S9: KB국민 | T9: (0000) 정상완료 | U9: 18991271 | V9: CAT(유선) | W9: 2636 | X9: 0 | Y9: FDIK | Z9: 7500 | AA9: (주)제일좋은솔루션 | AE9: 삼성 | AF9: 1247000 | AG9: 1218319 | AH9: 28681
A10: 108-85-35722 | B10: 신성통상에디션ANDZ퍼스트빌 | C10: 2022-08-01 | D10: 15:49:23 | E10: 9410-09**-****-1039 | F10: 05223852 | G10: 삼성 | H10: 188000 | I10: 입금완료 | J10: 승인 | K10: 정상 | L10: 2022-08-04 | M10: CAT | N10: 173060897 | O10: 4324 | P10: 183676 | Q10: 11908757 | S10: 삼성 | T10: (0000) 정상완료 | U10: 18991271 | V10: CAT(유선) | W10: 17090 | X10: 0 | Y10: FDIK | Z10: 7500 | AA10: (주)제일좋은솔루션 | AE10: 신한 | AF10: 1877500 | AG10: 1838966 | AH10: 38534
A11: 108-85-35722 | B11: 신성통상에디션ANDZ퍼스트빌 | C11: 2022-08-01 | D11: 17:06:50 | E11: 4574-92**-****-9906 | F11: 00468718 | G11: 현대 | H11: 196000 | I11: 입금완료 | J11: 승인 | K11: 정상 | L11: 2022-08-04 | M11: CAT | N11: 310963063 | O11: 4508 | P11: 191492 | Q11: 11908757 | S11: 현대 | T11: (0000) 정상완료 | U11: 18991271 | V11: CAT(유선) | W11: 17818 | X11: 0 | Y11: FDIK | Z11: 7500 | AA11: (주)제일좋은솔루션 | AE11: 외환 | AF11: 928000 | AG11: 803539 | AH11: 17461
A12: 108-85-35722 | B12: 신성통상에디션ANDZ퍼스트빌 | C12: 2022-08-01 | D12: 17:15:45 | E12: 6210-12**-****-2412 | F12: 70442181 | G12: 비씨 | H12: 118000 | I12: 입금완료 | J12: 승인 | K12: 정상 | L12: 2022-08-04 | M12: CAT | N12: 712781159 | O12: 1711 | P12: 116289 | Q12: 11908757 | S12: 비씨 | T12: (0000) 정상완료 | U12: 18991271 | V12: CAT(유선) | W12: 10727 | X12: 0 | Y12: FDIK | Z12: 7500 | AA12: (주)제일좋은솔루션 | AE12: 현대 | AF12: 1534400 | AG12: 1495787 | AH12: 35213
A13: 108-85-35722 | B13: 신성통상에디션ANDZ퍼스트빌 | C13: 2022-08-01 | D13: 18:21:03 | E13: 5188-31**-****-4474 | F13: 53276245 | G13: 삼성 | H13: 39000 | I13: 입금완료 | J13: 승인 | K13: 정상 | L13: 2022-08-04 | M13: CAT | N13: 173060897 | O13: 897 | P13: 38103 | Q13: 11908757 | S13: 삼성 | T13: (0000) 정상완료 | U13: 18991271 | V13: CAT(유선) | W13: 3545 | X13: 0 | Y13: FDIK | Z13: 7500 | AA13: (주)제일좋은솔루션 | AE13: 총합계 | AF13: 14905400 | AG13: 14429084 | AH13: 286916
A14: 108-85-35722 | B14: 신성통상에디션ANDZ퍼스트빌 | C14: 2022-08-01 | D14: 20:01:28 | E14: 4518-42**-****-7405 | F14: 04759762 | G14: 신한 | H14: 39000 | I14: 입금완료 | J14: 승인 | L14: 2022-08-04 | M14: CAT | N14: 0112786827 | O14: 897 | P14: 38103 | Q14: 11908757 | S14: 신한 | T14: (0000) 정상완료 | U14: 18991271 | V14: CAT(유선) | W14: 3545 | X14: 0 | Y14: FDIK | Z14: 7500 | AA14: (주)제일좋은솔루션
A15: 108-85-35722 | B15: 신성통상에디션ANDZ퍼스트빌 | C15: 2022-08-02 | D15: 13:21:38 | E15: 5387-20**-****-3812 | F15: 78162299 | G15: 비씨 | H15: 39000 | I15: 입금완료 | J15: 승인 | K15: 정상 | L15: 2022-08-05 | M15: CAT | N15: 712781159 | O15: 897 | P15: 38103 | Q15: 11908757 | S15: 비씨 | T15: (0000) 정상완료 | U15: 18991271 | V15: CAT(유선) | W15: 3545 | X15: 0 | Y15: FDIK | Z15: 7500 | AA15: (주)제일좋은솔루션
A16: 108-85-35722 | B16: 신성통상에디션ANDZ퍼스트빌 | C16: 2022-08-02 | D16: 13:48:03 | E16: 3569-08**-****-2907 | F16: 12246124 | G16: 신한 | H16: 39000 | I16: 입금완료 | J16: 승인 | L16: 2022-08-05 | M16: CAT | N16: 0112786827 | O16: 897 | P16: 38103 | Q16: 11908757 | S16: 신한 | T16: (0000) 정상완료 | U16: 18991271 | V16: CAT(유선) | W16: 3545 | X16: 0 | Y16: FDIK | Z16: 7500 | AA16: (주)제일좋은솔루션 | AE16: KB국민 | AF16: 2087000 | AG16: 2048444 | AH16: 38556 | AI16: =+AF16-AG16-AH16 -> 0
A17: 108-85-35722 | B17: 신성통상에디션ANDZ퍼스트빌 | C17: 2022-08-02 | D17: 14:39:08 | E17: 9430-16**-****-1026 | F17: 66457788 | G17: 농협 | H17: 49000 | I17: 입금완료 | J17: 승인 | L17: 2022-08-05 | M17: CAT | N17: 148832581 | O17: 1127 | P17: 47873 | Q17: 11908757 | S17: 농협 | T17: (0000) 정상완료 | U17: 18991271 | V17: CAT(유선) | W17: 4454 | X17: 0 | Y17: FDIK | Z17: 7500 | AA17: (주)제일좋은솔루션 | AE17: 농협 | AF17: 3486500 | AG17: 3421985 | AH17: 64515 | AI17: =+AF17-AG17-AH17 -> 0
A18: 108-85-35722 | B18: 신성통상에디션ANDZ퍼스트빌 | C18: 2022-08-02 | D18: 14:43:17 | E18: 5417-07**-****-5906 | F18: 28000151 | G18: 외환 | H18: 327000 | I18: 입금완료 | J18: 승인 | K18: 정상 | L18: 2022-08-05 | M18: CAT | N18: 00994444693 | O18: 7521 | P18: 319479 | Q18: 11908757 | S18: 하나 | T18: (0000) 정상완료 | U18: 18991271 | V18: CAT(유선) | W18: 29727 | X18: 0 | Y18: FDIK | Z18: 7500 | AA18: (주)제일좋은솔루션 | AE18: 롯데 | AF18: 521000 | AG18: 509017 | AH18: 11983 | AI18: =+AF18-AG18-AH18 -> 0
A19: 108-85-35722 | B19: 신성통상에디션ANDZ퍼스트빌 | C19: 2022-08-02 | D19: 15:30:25 | E19: 4364-20**-****-9522 | F19: 13562015 | G19: 신한 | H19: 100000 | I19: 입금완료 | J19: 승인 | L19: 2022-08-05 | M19: CAT | N19: 0112786827 | O19: 1500 | P19: 98500 | Q19: 11908757 | S19: 신한 | T19: (0000) 정상완료 | U19: 18991271 | V19: CAT(유선) | W19: 9090 | X19: 0 | Y19: FDIK | Z19: 7500 | AA19: (주)제일좋은솔루션 | AE19: 비씨 | AF19: 3224000 | AG19: 53790 | AH19: 3170210 | AI19: =+AF19-AG19-AH19 -> 0
A20: 108-85-35722 | B20: 신성통상에디션ANDZ퍼스트빌 | C20: 2022-08-02 | D20: 18:32:32 | E20: 4330-28**-****-7005 | F20: 00507644 | G20: 현대 | H20: 69000 | I20: 입금완료 | J20: 승인 | K20: 정상 | L20: 2022-08-05 | M20: CAT | N20: 310963063 | O20: 1587 | P20: 67413 | Q20: 11908757 | S20: 현대 | T20: (0000) 정상완료 | U20: 18991271 | V20: CAT(유선) | W20: 6272 | X20: 0 | Y20: FDIK | Z20: 7500 | AA20: (주)제일좋은솔루션 | AE20: 삼성 | AF20: 1247000 | AG20: 1218319 | AH20: 28681 | AI20: =+AF20-AG20-AH20 -> 0
A21: 108-85-35722 | B21: 신성통상에디션ANDZ퍼스트빌 | C21: 2022-08-03 | D21: 12:05:22 | E21: 4658-87**-****-0545 | F21: 22781068 | G21: 신한 | H21: 209000 | I21: 입금완료 | J21: 승인 | L21: 2022-08-08 | M21: CAT | N21: 0112786827 | O21: 4807 | P21: 204193 | Q21: 11908757 | S21: 신한 | T21: (0000) 정상완료 | U21: 18991271 | V21: CAT(유선) | W21: 19000 | X21: 0 | Y21: FDIK | Z21: 7500 | AA21: (주)제일좋은솔루션 | AE21: 신한 | AF21: 1877500 | AG21: 1838966 | AH21: 38534 | AI21: =+AF21-AG21-AH21 -> 0
A22: 108-85-35722 | B22: 신성통상에디션ANDZ퍼스트빌 | C22: 2022-08-03 | D22: 12:15:55 | E22: 4658-87**-****-0545 | F22: 22958245 | G22: 신한 | H22: 59000 | I22: 입금완료 | J22: 승인 | L22: 2022-08-08 | M22: CAT | N22: 0112786827 | O22: 1357 | P22: 57643 | Q22: 11908757 | S22: 신한 | T22: (0000) 정상완료 | U22: 18991271 | V22: CAT(유선) | W22: 5363 | X22: 0 | Y22: FDIK | Z22: 7500 | AA22: (주)제일좋은솔루션 | AE22: 외환 | AF22: 928000 | AG22: =103790+803539 -> 907329 | AH22: =3210+17461 -> 20671 | AI22: =+AF22-AG22-AH22 -> 0
A23: 108-85-35722 | B23: 신성통상에디션ANDZ퍼스트빌 | C23: 2022-08-03 | D23: 13:08:18 | E23: 5461-12**-****-2672 | F23: 74654570 | G23: 농협 | H23: 98000 | I23: 입금완료 | J23: 승인 | L23: 2022-08-08 | M23: CAT | N23: 148832581 | O23: 1421 | P23: 96579 | Q23: 11908757 | S23: 농협 | T23: (0000) 정상완료 | U23: 18991271 | V23: CAT(유선) | W23: 8909 | X23: 0 | Y23: FDIK | Z23: 7500 | AA23: (주)제일좋은솔루션 | AE23: 현대 | AF23: 1534400 | AG23: 1499109 | AH23: 35291 | AI23: =+AF23-AG23-AH23 -> 0
A24: 108-85-35722 | B24: 신성통상에디션ANDZ퍼스트빌 | C24: 2022-08-03 | D24: 13:26:56 | E24: 9440-03**-****-8267 | F24: 78808011 | G24: 비씨 | H24: 39000 | I24: 입금완료 | J24: 승인 | K24: 정상 | L24: 2022-08-08 | M24: CAT | N24: 712781159 | O24: 526 | P24: 38474 | Q24: 11908757 | S24: 비씨 | T24: (0000) 정상완료 | U24: 18991271 | V24: CAT(유선) | W24: 3545 | X24: 0 | Y24: FDIK | Z24: 7500 | AA24: (주)제일좋은솔루션
A25: 108-85-35722 | B25: 신성통상에디션ANDZ퍼스트빌 | C25: 2022-08-03 | D25: 16:05:17 | E25: 5461-12**-****-6060 | F25: 76655095 | G25: 농협 | H25: 58000 | I25: 입금완료 | J25: 승인 | L25: 2022-08-08 | M25: CAT | N25: 148832581 | O25: 841 | P25: 57159 | Q25: 11908757 | S25: 농협 | T25: (0000) 정상완료 | U25: 18991271 | V25: CAT(유선) | W25: 5272 | X25: 0 | Y25: FDIK | Z25: 7500 | AA25: (주)제일좋은솔루션
A26: 108-85-35722 | B26: 신성통상에디션ANDZ퍼스트빌 | C26: 2022-08-03 | D26: 18:07:19 | E26: 9420-12**-****-5274 | F26: 72639792 | G26: 비씨 | H26: 88000 | I26: 입금완료 | J26: 승인 | K26: 정상 | L26: 2022-08-08 | M26: CAT | N26: 712781159 | O26: 2024 | P26: 85976 | Q26: 11908757 | S26: 비씨 | T26: (0000) 정상완료 | U26: 18991271 | V26: CAT(유선) | W26: 8000 | X26: 0 | Y26: FDIK | Z26: 7500 | AA26: (주)제일좋은솔루션
A27: 108-85-35722 | B27: 신성통상에디션ANDZ퍼스트빌 | C27: 2022-08-03 | D27: 19:06:25 | E27: 4553-25**-****-4172 | F27: 61354239 | G27: 비씨 | H27: 167000 | I27: 입금완료 | J27: 승인 | K27: 정상 | L27: 2022-08-08 | M27: CAT | N27: 712781159 | O27: 3841 | P27: 163159 | Q27: 11908757 | S27: 비씨 | T27: (0000) 정상완료 | U27: 18991271 | V27: CAT(유선) | W27: 15181 | X27: 0 | Y27: FDIK | Z27: 7500 | AA27: (주)제일좋은솔루션
A28: 108-85-35722 | B28: 신성통상에디션ANDZ퍼스트빌 | C28: 2022-08-04 | D28: 12:07:58 | E28: 5138-94**-****-7547 | F28: 21318086 | G28: 롯데 | H28: 128000 | I28: 입금완료 | J28: 승인 | K28: 정상 | L28: 2022-08-09 | M28: CAT | N28: 9958307570 | O28: 2944 | P28: 125056 | Q28: 11908757 | S28: 롯데 | T28: (0000) 정상완료 | U28: 18991271 | V28: CAT(유선) | W28: 11636 | X28: 0 | Y28: FDIK | Z28: 7500 | AA28: (주)제일좋은솔루션
A29: 108-85-35722 | B29: 신성통상에디션ANDZ퍼스트빌 | C29: 2022-08-04 | D29: 12:23:48 | E29: 4742-89**-****-7675 | F29: 43095756 | G29: 삼성 | H29: 78000 | I29: 입금완료 | J29: 승인 | K29: 정상 | L29: 2022-08-09 | M29: CAT | N29: 173060897 | O29: 1794 | P29: 76206 | Q29: 11908757 | S29: 삼성 | T29: (0000) 정상완료 | U29: 18991271 | V29: CAT(유선) | W29: 7090 | X29: 0 | Y29: FDIK | Z29: 7500 | AA29: (주)제일좋은솔루션
A30: 108-85-35722 | B30: 신성통상에디션ANDZ퍼스트빌 | C30: 2022-08-04 | D30: 13:47:21 | E30: 4092-16**-****-4015 | F30: 47602490 | G30: 농협 | H30: 118000 | I30: 입금완료 | J30: 승인 | L30: 2022-08-09 | M30: CAT | N30: 148832581 | O30: 2714 | P30: 115286 | Q30: 11908757 | S30: 농협 | T30: (0000) 정상완료 | U30: 18991271 | V30: CAT(유선) | W30: 10727 | X30: 0 | Y30: FDIK | Z30: 7500 | AA30: (주)제일좋은솔루션
A31: 108-85-35722 | B31: 신성통상에디션ANDZ퍼스트빌 | C31: 2022-08-04 | D31: 15:52:02 | E31: 6243-31**-****-5710 | F31: 38740161 | G31: 신한 | H31: 119000 | I31: 입금완료 | J31: 승인 | L31: 2022-08-09 | M31: CAT | N31: 0112786827 | O31: 2737 | P31: 116263 | Q31: 11908757 | S31: 신한 | T31: (0000) 정상완료 | U31: 18991271 | V31: CAT(유선) | W31: 10818 | X31: 0 | Y31: FDIK | Z31: 7500 | AA31: (주)제일좋은솔루션
A32: 108-85-35722 | B32: 신성통상에디션ANDZ퍼스트빌 | C32: 2022-08-04 | D32: 16:55:55 | E32: 9441-16**-****-3129 | F32: 49662175 | G32: 농협 | H32: 68000 | I32: 입금완료 | J32: 승인 | L32: 2022-08-09 | M32: CAT | N32: 148832581 | O32: 986 | P32: 67014 | Q32: 11908757 | S32: 농협 | T32: (0000) 정상완료 | U32: 18991271 | V32: CAT(유선) | W32: 6181 | X32: 0 | Y32: FDIK | Z32: 7500 | AA32: (주)제일좋은솔루션
A33: 108-85-35722 | B33: 신성통상에디션ANDZ퍼스트빌 | C33: 2022-08-05 | D33: 12:23:07 | E33: 5424-16**-****-2417 | F33: 56139447 | G33: 농협 | H33: 206000 | I33: 입금완료 | J33: 승인 | L33: 2022-08-10 | M33: CAT | N33: 148832581 | O33: 4738 | P33: 201262 | Q33: 11908757 | S33: 농협 | T33: (0000) 정상완료 | U33: 18991271 | V33: CAT(유선) | W33: 18727 | X33: 0 | Y33: FDIK | Z33: 7500 | AA33: (주)제일좋은솔루션
A34: 108-85-35722 | B34: 신성통상에디션ANDZ퍼스트빌 | C34: 2022-08-05 | D34: 13:08:35 | E34: 5503-47**-****-2613 | F34: 00055356 | G34: 현대 | H34: 118000 | I34: 입금완료 | J34: 승인 | K34: 정상 | L34: 2022-08-10 | M34: CAT | N34: 310963063 | O34: 2714 | P34: 115286 | Q34: 11908757 | S34: 현대 | T34: (0000) 정상완료 | U34: 18991271 | V34: CAT(유선) | W34: 10727 | X34: 0 | Y34: FDIK | Z34: 7500 | AA34: (주)제일좋은솔루션
A35: 108-85-35722 | B35: 신성통상에디션ANDZ퍼스트빌 | C35: 2022-08-05 | D35: 13:29:19 | E35: 5461-11**-****-5150 | F35: 57002257 | G35: 농협 | H35: 69000 | I35: 입금완료 | J35: 승인 | L35: 2022-08-10 | M35: CAT | N35: 148832581 | O35: 1000 | P35: 68000 | Q35: 11908757 | S35: 농협 | T35: (0000) 정상완료 | U35: 18991271 | V35: CAT(유선) | W35: 6272 | X35: 0 | Y35: FDIK | Z35: 7500 | AA35: (주)제일좋은솔루션
A36: 108-85-35722 | B36: 신성통상에디션ANDZ퍼스트빌 | C36: 2022-08-05 | D36: 14:11:08 | E36: 5424-16**-****-4202 | F36: 57471004 | G36: 농협 | H36: 39000 | I36: 입금완료 | J36: 승인 | L36: 2022-08-10 | M36: CAT | N36: 148832581 | O36: 897 | P36: 38103 | Q36: 11908757 | S36: 농협 | T36: (0000) 정상완료 | U36: 18991271 | V36: CAT(유선) | W36: 3545 | X36: 0 | Y36: FDIK | Z36: 7500 | AA36: (주)제일좋은솔루션
A37: 108-85-35722 | B37: 신성통상에디션ANDZ퍼스트빌 | C37: 2022-08-05 | D37: 14:57:34 | E37: 9440-03**-****-7074 | F37: 72503402 | G37: 비씨 | H37: 39000 | I37: 입금완료 | J37: 승인 | K37: 정상 | L37: 2022-08-10 | M37: CAT | N37: 712781159 | O37: 526 | P37: 38474 | Q37: 11908757 | S37: 비씨 | T37: (0000) 정상완료 | U37: 18991271 | V37: CAT(유선) | W37: 3545 | X37: 0 | Y37: FDIK | Z37: 7500 | AA37: (주)제일좋은솔루션
A38: 108-85-35722 | B38: 신성통상에디션ANDZ퍼스트빌 | C38: 2022-08-05 | D38: 16:33:34 | E38: 4854-79**-****-0902 | F38: 59099749 | G38: 농협 | H38: 39000 | I38: 입금완료 | J38: 승인 | L38: 2022-08-10 | M38: CAT | N38: 148832581 | O38: 565 | P38: 38435 | Q38: 11908757 | S38: 농협 | T38: (0000) 정상완료 | U38: 18991271 | V38: CAT(유선) | W38: 3545 | X38: 0 | Y38: FDIK | Z38: 7500 | AA38: (주)제일좋은솔루션
A39: 108-85-35722 | B39: 신성통상에디션ANDZ퍼스트빌 | C39: 2022-08-05 | D39: 17:44:39 | E39: 4330-28**-****-4312 | F39: 00110978 | G39: 현대 | H39: 198000 | I39: 입금완료 | J39: 승인 | K39: 정상 | L39: 2022-08-10 | M39: CAT | N39: 310963063 | O39: 4554 | P39: 193446 | Q39: 11908757 | S39: 현대 | T39: (0000) 정상완료 | U39: 18991271 | V39: CAT(유선) | W39: 18000 | X39: 0 | Y39: FDIK | Z39: 7500 | AA39: (주)제일좋은솔루션
A40: 108-85-35722 | B40: 신성통상에디션ANDZ퍼스트빌 | C40: 2022-08-05 | D40: 18:15:56 | E40: 4033-02**-****-7919 | F40: 00127206 | G40: 현대 | H40: 69000 | I40: 입금완료 | J40: 승인 | K40: 정상 | L40: 2022-08-10 | M40: CAT | N40: 310963063 | O40: 1587 | P40: 67413 | Q40: 11908757 | S40: 현대 | T40: (0000) 정상완료 | U40: 18991271 | V40: CAT(유선) | W40: 6272 | X40: 0 | Y40: FDIK | Z40: 7500 | AA40: (주)제일좋은솔루션
A41: 108-85-35722 | B41: 신성통상에디션ANDZ퍼스트빌 | C41: 2022-08-06 | D41: 12:33:58 | E41: 9411-17**-****-3499 | F41: 66120079 | G41: 농협 | H41: 118000 | I41: 입금완료 | J41: 승인 | L41: 2022-08-10 | M41: CAT | N41: 148832581 | O41: 2714 | P41: 115286 | Q41: 11908757 | S41: 농협 | T41: (0000) 정상완료 | U41: 18991271 | V41: CAT(유선) | W41: 10727 | X41: 0 | Y41: FDIK | Z41: 7500 | AA41: (주)제일좋은솔루션
...

Sheet 미수관리(입금)
B2: 1. 판매 미수관리
B3: - FONE판매미수와 업체EDI 미수 관리 및 입금 관리
B5: 1) FONE 판매미수
B34: 2) 업체 판매미수
B62: 2. 공급 미수관리
B64: 1) FONE 공급미수
B104: 2) KONE 공급미수
P110: 합계 : | Q110: =6886040+10971236+32046234 -> 49903510
B111: 3) 업체 EDI 공급미수
W126: 합계 : | X126: =24659767+25243743 -> 49903510

Sheet 중간관리자
B2: 1. 중간관리자 수수료 세금계산서 발행 (역발행)
C3: - 계약된 수수료율로 계산서 발행(VAT별도)
C4: ** 공제금액포함 X, 지원금은 포함된 금액으로 발행
V37: 판매액 | W37: 수수료계산
U38: 오프라인 | V38: =2749000+484000 -> 3233000 | W38: =+V38*0.25 -> 808250
U39: 온라인 | V39: 156500 | W39: =+V39*0.18 -> 28170
W40: =+W39+W38 -> 836420
B57: 2. 중간관리자 공제내역 세금계산서 발행 (정발행)
C58: - 세금계산서는 회계팀에서 생성
C59: - 최종 지급 수수료 : 매출에 대한 수수료 - 공제액
U64: FONE 내역 확인

Sheet 요청사항
K15: 1. 누적 매출에 대한 슬라이딩 수수료
L16: - 누적 매출이 특정 구분단계를 초과하면 수수료 퍼센트에 변화
K17: 2. 매출 구간별 슬라이등 수수료
L18: - 특정 매출액을 초과시 초과분에 대한 수수료 퍼센트 변화
O19: 단위: 천단위
L20: 매출구간 | M20: 적용매출(예시) | N20: 수수료 | O20: 수수료 지급액
L21: 0-10,000 | M21: 10000 | N21: 0.18 | O21: =+M21*N21 -> 1800
L22: 10,001-20,000 | M22: 20000 | N22: 0.17 | O22: =+(M22-M21)*N22+O21 -> 3500
L23: 20,001-30,000 | M23: 30000 | N23: 0.15 | O23: =+(M23-M22)*N23+O22 -> 5000
